Setting up a new session...
Traceback (most recent call last):
  File "/usr/itetnas04/data-scratch-01/dlim_03hs20/data/conda_envs/machineLearning/lib/python3.7/site-packages/urllib3/connection.py", line 160, in _new_conn
    (self._dns_host, self.port), self.timeout, **extra_kw
  File "/usr/itetnas04/data-scratch-01/dlim_03hs20/data/conda_envs/machineLearning/lib/python3.7/site-packages/urllib3/util/connection.py", line 84, in create_connection
    raise err
  File "/usr/itetnas04/data-scratch-01/dlim_03hs20/data/conda_envs/machineLearning/lib/python3.7/site-packages/urllib3/util/connection.py", line 74, in create_connection
    sock.connect(sa)
ConnectionRefusedError: [Errno 111] Connection refused

During handling of the above exception, another exception occurred:

Traceback (most recent call last):
  File "/usr/itetnas04/data-scratch-01/dlim_03hs20/data/conda_envs/machineLearning/lib/python3.7/site-packages/urllib3/connectionpool.py", line 677, in urlopen
    chunked=chunked,
  File "/usr/itetnas04/data-scratch-01/dlim_03hs20/data/conda_envs/machineLearning/lib/python3.7/site-packages/urllib3/connectionpool.py", line 392, in _make_request
    conn.request(method, url, **httplib_request_kw)
  File "/usr/itetnas04/data-scratch-01/dlim_03hs20/data/conda_envs/machineLearning/lib/python3.7/http/client.py", line 1277, in request
    self._send_request(method, url, body, headers, encode_chunked)
  File "/usr/itetnas04/data-scratch-01/dlim_03hs20/data/conda_envs/machineLearning/lib/python3.7/http/client.py", line 1323, in _send_request
    self.endheaders(body, encode_chunked=encode_chunked)
  File "/usr/itetnas04/data-scratch-01/dlim_03hs20/data/conda_envs/machineLearning/lib/python3.7/http/client.py", line 1272, in endheaders
    self._send_output(message_body, encode_chunked=encode_chunked)
  File "/usr/itetnas04/data-scratch-01/dlim_03hs20/data/conda_envs/machineLearning/lib/python3.7/http/client.py", line 1032, in _send_output
    self.send(msg)
  File "/usr/itetnas04/data-scratch-01/dlim_03hs20/data/conda_envs/machineLearning/lib/python3.7/http/client.py", line 972, in send
    self.connect()
  File "/usr/itetnas04/data-scratch-01/dlim_03hs20/data/conda_envs/machineLearning/lib/python3.7/site-packages/urllib3/connection.py", line 187, in connect
    conn = self._new_conn()
  File "/usr/itetnas04/data-scratch-01/dlim_03hs20/data/conda_envs/machineLearning/lib/python3.7/site-packages/urllib3/connection.py", line 172, in _new_conn
    self, "Failed to establish a new connection: %s" % e
urllib3.exceptions.NewConnectionError: <urllib3.connection.HTTPConnection object at 0x7fcdcf79fb10>: Failed to establish a new connection: [Errno 111] Connection refused

During handling of the above exception, another exception occurred:

Traceback (most recent call last):
  File "/usr/itetnas04/data-scratch-01/dlim_03hs20/data/conda_envs/machineLearning/lib/python3.7/site-packages/requests/adapters.py", line 449, in send
    timeout=timeout
  File "/usr/itetnas04/data-scratch-01/dlim_03hs20/data/conda_envs/machineLearning/lib/python3.7/site-packages/urllib3/connectionpool.py", line 727, in urlopen
    method, url, error=e, _pool=self, _stacktrace=sys.exc_info()[2]
  File "/usr/itetnas04/data-scratch-01/dlim_03hs20/data/conda_envs/machineLearning/lib/python3.7/site-packages/urllib3/util/retry.py", line 439, in increment
    raise MaxRetryError(_pool, url, error or ResponseError(cause))
urllib3.exceptions.MaxRetryError: HTTPConnectionPool(host='localhost', port=8097): Max retries exceeded with url: /env/main (Caused by NewConnectionError('<urllib3.connection.HTTPConnection object at 0x7fcdcf79fb10>: Failed to establish a new connection: [Errno 111] Connection refused'))

During handling of the above exception, another exception occurred:

Traceback (most recent call last):
  File "/usr/itetnas04/data-scratch-01/dlim_03hs20/data/conda_envs/machineLearning/lib/python3.7/site-packages/visdom/__init__.py", line 711, in _send
    data=json.dumps(msg),
  File "/usr/itetnas04/data-scratch-01/dlim_03hs20/data/conda_envs/machineLearning/lib/python3.7/site-packages/visdom/__init__.py", line 677, in _handle_post
    r = self.session.post(url, data=data)
  File "/usr/itetnas04/data-scratch-01/dlim_03hs20/data/conda_envs/machineLearning/lib/python3.7/site-packages/requests/sessions.py", line 578, in post
    return self.request('POST', url, data=data, json=json, **kwargs)
  File "/usr/itetnas04/data-scratch-01/dlim_03hs20/data/conda_envs/machineLearning/lib/python3.7/site-packages/requests/sessions.py", line 530, in request
    resp = self.send(prep, **send_kwargs)
  File "/usr/itetnas04/data-scratch-01/dlim_03hs20/data/conda_envs/machineLearning/lib/python3.7/site-packages/requests/sessions.py", line 643, in send
    r = adapter.send(request, **kwargs)
  File "/usr/itetnas04/data-scratch-01/dlim_03hs20/data/conda_envs/machineLearning/lib/python3.7/site-packages/requests/adapters.py", line 516, in send
    raise ConnectionError(e, request=request)
requests.exceptions.ConnectionError: HTTPConnectionPool(host='localhost', port=8097): Max retries exceeded with url: /env/main (Caused by NewConnectionError('<urllib3.connection.HTTPConnection object at 0x7fcdcf79fb10>: Failed to establish a new connection: [Errno 111] Connection refused'))
[Errno 111] Connection refused
----------------- Options ---------------
               batch_size: 1                             
                    beta1: 0.5                           
          checkpoints_dir: ./checkpoints                 
           continue_train: False                         
                crop_size: 256                           
                 dataroot: ./datasets/facades            	[default: None]
             dataset_mode: aligned                       
                direction: BtoA                          	[default: AtoB]
              display_env: main                          
             display_freq: 400                           
               display_id: 1                             
            display_ncols: 4                             
             display_port: 8097                          
           display_server: http://localhost              
          display_winsize: 256                           
                    epoch: latest                        
              epoch_count: 1                             
                 gan_mode: vanilla                       
                  gpu_ids: 0                             
                init_gain: 0.02                          
                init_type: normal                        
                 input_nc: 3                             
                  isTrain: True                          	[default: None]
                lambda_L1: 100.0                         
                load_iter: 0                             	[default: 0]
                load_size: 286                           
                       lr: 0.0002                        
           lr_decay_iters: 50                            
                lr_policy: linear                        
         max_dataset_size: inf                           
                    model: stochastic                    	[default: cycle_gan]
                 n_epochs: 100                           
           n_epochs_decay: 100                           
               n_layers_D: 3                             
                     name: stoch                         	[default: experiment_name]
                      ndf: 64                            
                     netD: basic                         
                     netG: unet_256                      
                      ngf: 64                            
               no_dropout: False                         
                  no_flip: False                         
                  no_html: False                         
                     norm: batch                         
              num_threads: 4                             
                output_nc: 3                             
                    phase: train                         
                pool_size: 0                             
               preprocess: resize_and_crop               
               print_freq: 100                           
             save_by_iter: False                         
          save_epoch_freq: 5                             
         save_latest_freq: 5000                          
           serial_batches: False                         
                   suffix:                               
         update_html_freq: 1000                          
                  verbose: False                         
----------------- End -------------------
dataset [AlignedDataset] was created
The number of training images = 400
initialize network with normal
initialize network with normal
model [StochasticModel] was created
---------- Networks initialized -------------
[Network G] Total number of parameters : 54.414 M
[Network D] Total number of parameters : 2.769 M
-----------------------------------------------
Exception in user code:
------------------------------------------------------------


Could not connect to Visdom server. 
 Trying to start a server....
Command: /usr/itetnas04/data-scratch-01/dlim_03hs20/data/conda_envs/machineLearning/bin/python -m visdom.server -p 8097 &>/dev/null &
create web directory ./checkpoints/stoch/web...
learning rate 0.0002000 -> 0.0002000
(epoch: 1, iters: 100, time: 0.056, data: 0.282) G_GAN: 0.628 G_L1: 25.965 D_real: 1.407 D_fake: 0.313 
Exception in user code:
------------------------------------------------------------
(epoch: 1, iters: 200, time: 0.057, data: 0.002) G_GAN: 2.628 G_L1: 43.916 D_real: 0.039 D_fake: 0.169 
Exception in user code:
------------------------------------------------------------
(epoch: 1, iters: 300, time: 0.060, data: 0.002) G_GAN: 1.764 G_L1: 31.740 D_real: 0.280 D_fake: 0.095 
Exception in user code:
------------------------------------------------------------
Exception in user code:
------------------------------------------------------------
Exception in user code:
------------------------------------------------------------
(epoch: 1, iters: 400, time: 0.255, data: 0.002) G_GAN: 1.191 G_L1: 50.201 D_real: 0.462 D_fake: 0.200 
Exception in user code:
------------------------------------------------------------
End of epoch 1 / 200 	 Time Taken: 22 sec
learning rate 0.0002000 -> 0.0002000
Traceback (most recent call last):
  File "/usr/itetnas04/data-scratch-01/dlim_03hs20/data/conda_envs/machineLearning/lib/python3.7/site-packages/urllib3/connection.py", line 160, in _new_conn
    (self._dns_host, self.port), self.timeout, **extra_kw
  File "/usr/itetnas04/data-scratch-01/dlim_03hs20/data/conda_envs/machineLearning/lib/python3.7/site-packages/urllib3/util/connection.py", line 84, in create_connection
    raise err
  File "/usr/itetnas04/data-scratch-01/dlim_03hs20/data/conda_envs/machineLearning/lib/python3.7/site-packages/urllib3/util/connection.py", line 74, in create_connection
    sock.connect(sa)
ConnectionRefusedError: [Errno 111] Connection refused

During handling of the above exception, another exception occurred:

Traceback (most recent call last):
  File "/usr/itetnas04/data-scratch-01/dlim_03hs20/data/conda_envs/machineLearning/lib/python3.7/site-packages/urllib3/connectionpool.py", line 677, in urlopen
    chunked=chunked,
  File "/usr/itetnas04/data-scratch-01/dlim_03hs20/data/conda_envs/machineLearning/lib/python3.7/site-packages/urllib3/connectionpool.py", line 392, in _make_request
    conn.request(method, url, **httplib_request_kw)
  File "/usr/itetnas04/data-scratch-01/dlim_03hs20/data/conda_envs/machineLearning/lib/python3.7/http/client.py", line 1277, in request
    self._send_request(method, url, body, headers, encode_chunked)
  File "/usr/itetnas04/data-scratch-01/dlim_03hs20/data/conda_envs/machineLearning/lib/python3.7/http/client.py", line 1323, in _send_request
    self.endheaders(body, encode_chunked=encode_chunked)
  File "/usr/itetnas04/data-scratch-01/dlim_03hs20/data/conda_envs/machineLearning/lib/python3.7/http/client.py", line 1272, in endheaders
    self._send_output(message_body, encode_chunked=encode_chunked)
  File "/usr/itetnas04/data-scratch-01/dlim_03hs20/data/conda_envs/machineLearning/lib/python3.7/http/client.py", line 1032, in _send_output
    self.send(msg)
  File "/usr/itetnas04/data-scratch-01/dlim_03hs20/data/conda_envs/machineLearning/lib/python3.7/http/client.py", line 972, in send
    self.connect()
  File "/usr/itetnas04/data-scratch-01/dlim_03hs20/data/conda_envs/machineLearning/lib/python3.7/site-packages/urllib3/connection.py", line 187, in connect
    conn = self._new_conn()
  File "/usr/itetnas04/data-scratch-01/dlim_03hs20/data/conda_envs/machineLearning/lib/python3.7/site-packages/urllib3/connection.py", line 172, in _new_conn
    self, "Failed to establish a new connection: %s" % e
urllib3.exceptions.NewConnectionError: <urllib3.connection.HTTPConnection object at 0x7fcd7a53e990>: Failed to establish a new connection: [Errno 111] Connection refused

During handling of the above exception, another exception occurred:

Traceback (most recent call last):
  File "/usr/itetnas04/data-scratch-01/dlim_03hs20/data/conda_envs/machineLearning/lib/python3.7/site-packages/requests/adapters.py", line 449, in send
    timeout=timeout
  File "/usr/itetnas04/data-scratch-01/dlim_03hs20/data/conda_envs/machineLearning/lib/python3.7/site-packages/urllib3/connectionpool.py", line 727, in urlopen
    method, url, error=e, _pool=self, _stacktrace=sys.exc_info()[2]
  File "/usr/itetnas04/data-scratch-01/dlim_03hs20/data/conda_envs/machineLearning/lib/python3.7/site-packages/urllib3/util/retry.py", line 439, in increment
    raise MaxRetryError(_pool, url, error or ResponseError(cause))
urllib3.exceptions.MaxRetryError: HTTPConnectionPool(host='localhost', port=8097): Max retries exceeded with url: /events (Caused by NewConnectionError('<urllib3.connection.HTTPConnection object at 0x7fcd7a53e990>: Failed to establish a new connection: [Errno 111] Connection refused'))

During handling of the above exception, another exception occurred:

Traceback (most recent call last):
  File "/usr/itetnas04/data-scratch-01/dlim_03hs20/data/conda_envs/machineLearning/lib/python3.7/site-packages/visdom/__init__.py", line 711, in _send
    data=json.dumps(msg),
  File "/usr/itetnas04/data-scratch-01/dlim_03hs20/data/conda_envs/machineLearning/lib/python3.7/site-packages/visdom/__init__.py", line 677, in _handle_post
    r = self.session.post(url, data=data)
  File "/usr/itetnas04/data-scratch-01/dlim_03hs20/data/conda_envs/machineLearning/lib/python3.7/site-packages/requests/sessions.py", line 578, in post
    return self.request('POST', url, data=data, json=json, **kwargs)
  File "/usr/itetnas04/data-scratch-01/dlim_03hs20/data/conda_envs/machineLearning/lib/python3.7/site-packages/requests/sessions.py", line 530, in request
    resp = self.send(prep, **send_kwargs)
  File "/usr/itetnas04/data-scratch-01/dlim_03hs20/data/conda_envs/machineLearning/lib/python3.7/site-packages/requests/sessions.py", line 643, in send
    r = adapter.send(request, **kwargs)
  File "/usr/itetnas04/data-scratch-01/dlim_03hs20/data/conda_envs/machineLearning/lib/python3.7/site-packages/requests/adapters.py", line 516, in send
    raise ConnectionError(e, request=request)
requests.exceptions.ConnectionError: HTTPConnectionPool(host='localhost', port=8097): Max retries exceeded with url: /events (Caused by NewConnectionError('<urllib3.connection.HTTPConnection object at 0x7fcd7a53e990>: Failed to establish a new connection: [Errno 111] Connection refused'))
Traceback (most recent call last):
  File "/usr/itetnas04/data-scratch-01/dlim_03hs20/data/conda_envs/machineLearning/lib/python3.7/site-packages/urllib3/connection.py", line 160, in _new_conn
    (self._dns_host, self.port), self.timeout, **extra_kw
  File "/usr/itetnas04/data-scratch-01/dlim_03hs20/data/conda_envs/machineLearning/lib/python3.7/site-packages/urllib3/util/connection.py", line 84, in create_connection
    raise err
  File "/usr/itetnas04/data-scratch-01/dlim_03hs20/data/conda_envs/machineLearning/lib/python3.7/site-packages/urllib3/util/connection.py", line 74, in create_connection
    sock.connect(sa)
ConnectionRefusedError: [Errno 111] Connection refused

During handling of the above exception, another exception occurred:

Traceback (most recent call last):
  File "/usr/itetnas04/data-scratch-01/dlim_03hs20/data/conda_envs/machineLearning/lib/python3.7/site-packages/urllib3/connectionpool.py", line 677, in urlopen
    chunked=chunked,
  File "/usr/itetnas04/data-scratch-01/dlim_03hs20/data/conda_envs/machineLearning/lib/python3.7/site-packages/urllib3/connectionpool.py", line 392, in _make_request
    conn.request(method, url, **httplib_request_kw)
  File "/usr/itetnas04/data-scratch-01/dlim_03hs20/data/conda_envs/machineLearning/lib/python3.7/http/client.py", line 1277, in request
    self._send_request(method, url, body, headers, encode_chunked)
  File "/usr/itetnas04/data-scratch-01/dlim_03hs20/data/conda_envs/machineLearning/lib/python3.7/http/client.py", line 1323, in _send_request
    self.endheaders(body, encode_chunked=encode_chunked)
  File "/usr/itetnas04/data-scratch-01/dlim_03hs20/data/conda_envs/machineLearning/lib/python3.7/http/client.py", line 1272, in endheaders
    self._send_output(message_body, encode_chunked=encode_chunked)
  File "/usr/itetnas04/data-scratch-01/dlim_03hs20/data/conda_envs/machineLearning/lib/python3.7/http/client.py", line 1032, in _send_output
    self.send(msg)
  File "/usr/itetnas04/data-scratch-01/dlim_03hs20/data/conda_envs/machineLearning/lib/python3.7/http/client.py", line 972, in send
    self.connect()
  File "/usr/itetnas04/data-scratch-01/dlim_03hs20/data/conda_envs/machineLearning/lib/python3.7/site-packages/urllib3/connection.py", line 187, in connect
    conn = self._new_conn()
  File "/usr/itetnas04/data-scratch-01/dlim_03hs20/data/conda_envs/machineLearning/lib/python3.7/site-packages/urllib3/connection.py", line 172, in _new_conn
    self, "Failed to establish a new connection: %s" % e
urllib3.exceptions.NewConnectionError: <urllib3.connection.HTTPConnection object at 0x7fcd7a355e50>: Failed to establish a new connection: [Errno 111] Connection refused

During handling of the above exception, another exception occurred:

Traceback (most recent call last):
  File "/usr/itetnas04/data-scratch-01/dlim_03hs20/data/conda_envs/machineLearning/lib/python3.7/site-packages/requests/adapters.py", line 449, in send
    timeout=timeout
  File "/usr/itetnas04/data-scratch-01/dlim_03hs20/data/conda_envs/machineLearning/lib/python3.7/site-packages/urllib3/connectionpool.py", line 727, in urlopen
    method, url, error=e, _pool=self, _stacktrace=sys.exc_info()[2]
  File "/usr/itetnas04/data-scratch-01/dlim_03hs20/data/conda_envs/machineLearning/lib/python3.7/site-packages/urllib3/util/retry.py", line 439, in increment
    raise MaxRetryError(_pool, url, error or ResponseError(cause))
urllib3.exceptions.MaxRetryError: HTTPConnectionPool(host='localhost', port=8097): Max retries exceeded with url: /events (Caused by NewConnectionError('<urllib3.connection.HTTPConnection object at 0x7fcd7a355e50>: Failed to establish a new connection: [Errno 111] Connection refused'))

During handling of the above exception, another exception occurred:

Traceback (most recent call last):
  File "/usr/itetnas04/data-scratch-01/dlim_03hs20/data/conda_envs/machineLearning/lib/python3.7/site-packages/visdom/__init__.py", line 711, in _send
    data=json.dumps(msg),
  File "/usr/itetnas04/data-scratch-01/dlim_03hs20/data/conda_envs/machineLearning/lib/python3.7/site-packages/visdom/__init__.py", line 677, in _handle_post
    r = self.session.post(url, data=data)
  File "/usr/itetnas04/data-scratch-01/dlim_03hs20/data/conda_envs/machineLearning/lib/python3.7/site-packages/requests/sessions.py", line 578, in post
    return self.request('POST', url, data=data, json=json, **kwargs)
  File "/usr/itetnas04/data-scratch-01/dlim_03hs20/data/conda_envs/machineLearning/lib/python3.7/site-packages/requests/sessions.py", line 530, in request
    resp = self.send(prep, **send_kwargs)
  File "/usr/itetnas04/data-scratch-01/dlim_03hs20/data/conda_envs/machineLearning/lib/python3.7/site-packages/requests/sessions.py", line 643, in send
    r = adapter.send(request, **kwargs)
  File "/usr/itetnas04/data-scratch-01/dlim_03hs20/data/conda_envs/machineLearning/lib/python3.7/site-packages/requests/adapters.py", line 516, in send
    raise ConnectionError(e, request=request)
requests.exceptions.ConnectionError: HTTPConnectionPool(host='localhost', port=8097): Max retries exceeded with url: /events (Caused by NewConnectionError('<urllib3.connection.HTTPConnection object at 0x7fcd7a355e50>: Failed to establish a new connection: [Errno 111] Connection refused'))
Traceback (most recent call last):
  File "/usr/itetnas04/data-scratch-01/dlim_03hs20/data/conda_envs/machineLearning/lib/python3.7/site-packages/urllib3/connection.py", line 160, in _new_conn
    (self._dns_host, self.port), self.timeout, **extra_kw
  File "/usr/itetnas04/data-scratch-01/dlim_03hs20/data/conda_envs/machineLearning/lib/python3.7/site-packages/urllib3/util/connection.py", line 84, in create_connection
    raise err
  File "/usr/itetnas04/data-scratch-01/dlim_03hs20/data/conda_envs/machineLearning/lib/python3.7/site-packages/urllib3/util/connection.py", line 74, in create_connection
    sock.connect(sa)
ConnectionRefusedError: [Errno 111] Connection refused

During handling of the above exception, another exception occurred:

Traceback (most recent call last):
  File "/usr/itetnas04/data-scratch-01/dlim_03hs20/data/conda_envs/machineLearning/lib/python3.7/site-packages/urllib3/connectionpool.py", line 677, in urlopen
    chunked=chunked,
  File "/usr/itetnas04/data-scratch-01/dlim_03hs20/data/conda_envs/machineLearning/lib/python3.7/site-packages/urllib3/connectionpool.py", line 392, in _make_request
    conn.request(method, url, **httplib_request_kw)
  File "/usr/itetnas04/data-scratch-01/dlim_03hs20/data/conda_envs/machineLearning/lib/python3.7/http/client.py", line 1277, in request
    self._send_request(method, url, body, headers, encode_chunked)
  File "/usr/itetnas04/data-scratch-01/dlim_03hs20/data/conda_envs/machineLearning/lib/python3.7/http/client.py", line 1323, in _send_request
    self.endheaders(body, encode_chunked=encode_chunked)
  File "/usr/itetnas04/data-scratch-01/dlim_03hs20/data/conda_envs/machineLearning/lib/python3.7/http/client.py", line 1272, in endheaders
    self._send_output(message_body, encode_chunked=encode_chunked)
  File "/usr/itetnas04/data-scratch-01/dlim_03hs20/data/conda_envs/machineLearning/lib/python3.7/http/client.py", line 1032, in _send_output
    self.send(msg)
  File "/usr/itetnas04/data-scratch-01/dlim_03hs20/data/conda_envs/machineLearning/lib/python3.7/http/client.py", line 972, in send
    self.connect()
  File "/usr/itetnas04/data-scratch-01/dlim_03hs20/data/conda_envs/machineLearning/lib/python3.7/site-packages/urllib3/connection.py", line 187, in connect
    conn = self._new_conn()
  File "/usr/itetnas04/data-scratch-01/dlim_03hs20/data/conda_envs/machineLearning/lib/python3.7/site-packages/urllib3/connection.py", line 172, in _new_conn
    self, "Failed to establish a new connection: %s" % e
urllib3.exceptions.NewConnectionError: <urllib3.connection.HTTPConnection object at 0x7fcd7a35e1d0>: Failed to establish a new connection: [Errno 111] Connection refused

During handling of the above exception, another exception occurred:

Traceback (most recent call last):
  File "/usr/itetnas04/data-scratch-01/dlim_03hs20/data/conda_envs/machineLearning/lib/python3.7/site-packages/requests/adapters.py", line 449, in send
    timeout=timeout
  File "/usr/itetnas04/data-scratch-01/dlim_03hs20/data/conda_envs/machineLearning/lib/python3.7/site-packages/urllib3/connectionpool.py", line 727, in urlopen
    method, url, error=e, _pool=self, _stacktrace=sys.exc_info()[2]
  File "/usr/itetnas04/data-scratch-01/dlim_03hs20/data/conda_envs/machineLearning/lib/python3.7/site-packages/urllib3/util/retry.py", line 439, in increment
    raise MaxRetryError(_pool, url, error or ResponseError(cause))
urllib3.exceptions.MaxRetryError: HTTPConnectionPool(host='localhost', port=8097): Max retries exceeded with url: /events (Caused by NewConnectionError('<urllib3.connection.HTTPConnection object at 0x7fcd7a35e1d0>: Failed to establish a new connection: [Errno 111] Connection refused'))

During handling of the above exception, another exception occurred:

Traceback (most recent call last):
  File "/usr/itetnas04/data-scratch-01/dlim_03hs20/data/conda_envs/machineLearning/lib/python3.7/site-packages/visdom/__init__.py", line 711, in _send
    data=json.dumps(msg),
  File "/usr/itetnas04/data-scratch-01/dlim_03hs20/data/conda_envs/machineLearning/lib/python3.7/site-packages/visdom/__init__.py", line 677, in _handle_post
    r = self.session.post(url, data=data)
  File "/usr/itetnas04/data-scratch-01/dlim_03hs20/data/conda_envs/machineLearning/lib/python3.7/site-packages/requests/sessions.py", line 578, in post
    return self.request('POST', url, data=data, json=json, **kwargs)
  File "/usr/itetnas04/data-scratch-01/dlim_03hs20/data/conda_envs/machineLearning/lib/python3.7/site-packages/requests/sessions.py", line 530, in request
    resp = self.send(prep, **send_kwargs)
  File "/usr/itetnas04/data-scratch-01/dlim_03hs20/data/conda_envs/machineLearning/lib/python3.7/site-packages/requests/sessions.py", line 643, in send
    r = adapter.send(request, **kwargs)
  File "/usr/itetnas04/data-scratch-01/dlim_03hs20/data/conda_envs/machineLearning/lib/python3.7/site-packages/requests/adapters.py", line 516, in send
    raise ConnectionError(e, request=request)
requests.exceptions.ConnectionError: HTTPConnectionPool(host='localhost', port=8097): Max retries exceeded with url: /events (Caused by NewConnectionError('<urllib3.connection.HTTPConnection object at 0x7fcd7a35e1d0>: Failed to establish a new connection: [Errno 111] Connection refused'))
Traceback (most recent call last):
  File "/usr/itetnas04/data-scratch-01/dlim_03hs20/data/conda_envs/machineLearning/lib/python3.7/site-packages/urllib3/connection.py", line 160, in _new_conn
    (self._dns_host, self.port), self.timeout, **extra_kw
  File "/usr/itetnas04/data-scratch-01/dlim_03hs20/data/conda_envs/machineLearning/lib/python3.7/site-packages/urllib3/util/connection.py", line 84, in create_connection
    raise err
  File "/usr/itetnas04/data-scratch-01/dlim_03hs20/data/conda_envs/machineLearning/lib/python3.7/site-packages/urllib3/util/connection.py", line 74, in create_connection
    sock.connect(sa)
ConnectionRefusedError: [Errno 111] Connection refused

During handling of the above exception, another exception occurred:

Traceback (most recent call last):
  File "/usr/itetnas04/data-scratch-01/dlim_03hs20/data/conda_envs/machineLearning/lib/python3.7/site-packages/urllib3/connectionpool.py", line 677, in urlopen
    chunked=chunked,
  File "/usr/itetnas04/data-scratch-01/dlim_03hs20/data/conda_envs/machineLearning/lib/python3.7/site-packages/urllib3/connectionpool.py", line 392, in _make_request
    conn.request(method, url, **httplib_request_kw)
  File "/usr/itetnas04/data-scratch-01/dlim_03hs20/data/conda_envs/machineLearning/lib/python3.7/http/client.py", line 1277, in request
    self._send_request(method, url, body, headers, encode_chunked)
  File "/usr/itetnas04/data-scratch-01/dlim_03hs20/data/conda_envs/machineLearning/lib/python3.7/http/client.py", line 1323, in _send_request
    self.endheaders(body, encode_chunked=encode_chunked)
  File "/usr/itetnas04/data-scratch-01/dlim_03hs20/data/conda_envs/machineLearning/lib/python3.7/http/client.py", line 1272, in endheaders
    self._send_output(message_body, encode_chunked=encode_chunked)
  File "/usr/itetnas04/data-scratch-01/dlim_03hs20/data/conda_envs/machineLearning/lib/python3.7/http/client.py", line 1032, in _send_output
    self.send(msg)
  File "/usr/itetnas04/data-scratch-01/dlim_03hs20/data/conda_envs/machineLearning/lib/python3.7/http/client.py", line 972, in send
    self.connect()
  File "/usr/itetnas04/data-scratch-01/dlim_03hs20/data/conda_envs/machineLearning/lib/python3.7/site-packages/urllib3/connection.py", line 187, in connect
    conn = self._new_conn()
  File "/usr/itetnas04/data-scratch-01/dlim_03hs20/data/conda_envs/machineLearning/lib/python3.7/site-packages/urllib3/connection.py", line 172, in _new_conn
    self, "Failed to establish a new connection: %s" % e
urllib3.exceptions.NewConnectionError: <urllib3.connection.HTTPConnection object at 0x7fcd7a3d9050>: Failed to establish a new connection: [Errno 111] Connection refused

During handling of the above exception, another exception occurred:

Traceback (most recent call last):
  File "/usr/itetnas04/data-scratch-01/dlim_03hs20/data/conda_envs/machineLearning/lib/python3.7/site-packages/requests/adapters.py", line 449, in send
    timeout=timeout
  File "/usr/itetnas04/data-scratch-01/dlim_03hs20/data/conda_envs/machineLearning/lib/python3.7/site-packages/urllib3/connectionpool.py", line 727, in urlopen
    method, url, error=e, _pool=self, _stacktrace=sys.exc_info()[2]
  File "/usr/itetnas04/data-scratch-01/dlim_03hs20/data/conda_envs/machineLearning/lib/python3.7/site-packages/urllib3/util/retry.py", line 439, in increment
    raise MaxRetryError(_pool, url, error or ResponseError(cause))
urllib3.exceptions.MaxRetryError: HTTPConnectionPool(host='localhost', port=8097): Max retries exceeded with url: /events (Caused by NewConnectionError('<urllib3.connection.HTTPConnection object at 0x7fcd7a3d9050>: Failed to establish a new connection: [Errno 111] Connection refused'))

During handling of the above exception, another exception occurred:

Traceback (most recent call last):
  File "/usr/itetnas04/data-scratch-01/dlim_03hs20/data/conda_envs/machineLearning/lib/python3.7/site-packages/visdom/__init__.py", line 711, in _send
    data=json.dumps(msg),
  File "/usr/itetnas04/data-scratch-01/dlim_03hs20/data/conda_envs/machineLearning/lib/python3.7/site-packages/visdom/__init__.py", line 677, in _handle_post
    r = self.session.post(url, data=data)
  File "/usr/itetnas04/data-scratch-01/dlim_03hs20/data/conda_envs/machineLearning/lib/python3.7/site-packages/requests/sessions.py", line 578, in post
    return self.request('POST', url, data=data, json=json, **kwargs)
  File "/usr/itetnas04/data-scratch-01/dlim_03hs20/data/conda_envs/machineLearning/lib/python3.7/site-packages/requests/sessions.py", line 530, in request
    resp = self.send(prep, **send_kwargs)
  File "/usr/itetnas04/data-scratch-01/dlim_03hs20/data/conda_envs/machineLearning/lib/python3.7/site-packages/requests/sessions.py", line 643, in send
    r = adapter.send(request, **kwargs)
  File "/usr/itetnas04/data-scratch-01/dlim_03hs20/data/conda_envs/machineLearning/lib/python3.7/site-packages/requests/adapters.py", line 516, in send
    raise ConnectionError(e, request=request)
requests.exceptions.ConnectionError: HTTPConnectionPool(host='localhost', port=8097): Max retries exceeded with url: /events (Caused by NewConnectionError('<urllib3.connection.HTTPConnection object at 0x7fcd7a3d9050>: Failed to establish a new connection: [Errno 111] Connection refused'))
Traceback (most recent call last):
  File "/usr/itetnas04/data-scratch-01/dlim_03hs20/data/conda_envs/machineLearning/lib/python3.7/site-packages/urllib3/connection.py", line 160, in _new_conn
    (self._dns_host, self.port), self.timeout, **extra_kw
  File "/usr/itetnas04/data-scratch-01/dlim_03hs20/data/conda_envs/machineLearning/lib/python3.7/site-packages/urllib3/util/connection.py", line 84, in create_connection
    raise err
  File "/usr/itetnas04/data-scratch-01/dlim_03hs20/data/conda_envs/machineLearning/lib/python3.7/site-packages/urllib3/util/connection.py", line 74, in create_connection
    sock.connect(sa)
ConnectionRefusedError: [Errno 111] Connection refused

During handling of the above exception, another exception occurred:

Traceback (most recent call last):
  File "/usr/itetnas04/data-scratch-01/dlim_03hs20/data/conda_envs/machineLearning/lib/python3.7/site-packages/urllib3/connectionpool.py", line 677, in urlopen
    chunked=chunked,
  File "/usr/itetnas04/data-scratch-01/dlim_03hs20/data/conda_envs/machineLearning/lib/python3.7/site-packages/urllib3/connectionpool.py", line 392, in _make_request
    conn.request(method, url, **httplib_request_kw)
  File "/usr/itetnas04/data-scratch-01/dlim_03hs20/data/conda_envs/machineLearning/lib/python3.7/http/client.py", line 1277, in request
    self._send_request(method, url, body, headers, encode_chunked)
  File "/usr/itetnas04/data-scratch-01/dlim_03hs20/data/conda_envs/machineLearning/lib/python3.7/http/client.py", line 1323, in _send_request
    self.endheaders(body, encode_chunked=encode_chunked)
  File "/usr/itetnas04/data-scratch-01/dlim_03hs20/data/conda_envs/machineLearning/lib/python3.7/http/client.py", line 1272, in endheaders
    self._send_output(message_body, encode_chunked=encode_chunked)
  File "/usr/itetnas04/data-scratch-01/dlim_03hs20/data/conda_envs/machineLearning/lib/python3.7/http/client.py", line 1032, in _send_output
    self.send(msg)
  File "/usr/itetnas04/data-scratch-01/dlim_03hs20/data/conda_envs/machineLearning/lib/python3.7/http/client.py", line 972, in send
    self.connect()
  File "/usr/itetnas04/data-scratch-01/dlim_03hs20/data/conda_envs/machineLearning/lib/python3.7/site-packages/urllib3/connection.py", line 187, in connect
    conn = self._new_conn()
  File "/usr/itetnas04/data-scratch-01/dlim_03hs20/data/conda_envs/machineLearning/lib/python3.7/site-packages/urllib3/connection.py", line 172, in _new_conn
    self, "Failed to establish a new connection: %s" % e
urllib3.exceptions.NewConnectionError: <urllib3.connection.HTTPConnection object at 0x7fcd7a3d9850>: Failed to establish a new connection: [Errno 111] Connection refused

During handling of the above exception, another exception occurred:

Traceback (most recent call last):
  File "/usr/itetnas04/data-scratch-01/dlim_03hs20/data/conda_envs/machineLearning/lib/python3.7/site-packages/requests/adapters.py", line 449, in send
    timeout=timeout
  File "/usr/itetnas04/data-scratch-01/dlim_03hs20/data/conda_envs/machineLearning/lib/python3.7/site-packages/urllib3/connectionpool.py", line 727, in urlopen
    method, url, error=e, _pool=self, _stacktrace=sys.exc_info()[2]
  File "/usr/itetnas04/data-scratch-01/dlim_03hs20/data/conda_envs/machineLearning/lib/python3.7/site-packages/urllib3/util/retry.py", line 439, in increment
    raise MaxRetryError(_pool, url, error or ResponseError(cause))
urllib3.exceptions.MaxRetryError: HTTPConnectionPool(host='localhost', port=8097): Max retries exceeded with url: /events (Caused by NewConnectionError('<urllib3.connection.HTTPConnection object at 0x7fcd7a3d9850>: Failed to establish a new connection: [Errno 111] Connection refused'))

During handling of the above exception, another exception occurred:

Traceback (most recent call last):
  File "/usr/itetnas04/data-scratch-01/dlim_03hs20/data/conda_envs/machineLearning/lib/python3.7/site-packages/visdom/__init__.py", line 711, in _send
    data=json.dumps(msg),
  File "/usr/itetnas04/data-scratch-01/dlim_03hs20/data/conda_envs/machineLearning/lib/python3.7/site-packages/visdom/__init__.py", line 677, in _handle_post
    r = self.session.post(url, data=data)
  File "/usr/itetnas04/data-scratch-01/dlim_03hs20/data/conda_envs/machineLearning/lib/python3.7/site-packages/requests/sessions.py", line 578, in post
    return self.request('POST', url, data=data, json=json, **kwargs)
  File "/usr/itetnas04/data-scratch-01/dlim_03hs20/data/conda_envs/machineLearning/lib/python3.7/site-packages/requests/sessions.py", line 530, in request
    resp = self.send(prep, **send_kwargs)
  File "/usr/itetnas04/data-scratch-01/dlim_03hs20/data/conda_envs/machineLearning/lib/python3.7/site-packages/requests/sessions.py", line 643, in send
    r = adapter.send(request, **kwargs)
  File "/usr/itetnas04/data-scratch-01/dlim_03hs20/data/conda_envs/machineLearning/lib/python3.7/site-packages/requests/adapters.py", line 516, in send
    raise ConnectionError(e, request=request)
requests.exceptions.ConnectionError: HTTPConnectionPool(host='localhost', port=8097): Max retries exceeded with url: /events (Caused by NewConnectionError('<urllib3.connection.HTTPConnection object at 0x7fcd7a3d9850>: Failed to establish a new connection: [Errno 111] Connection refused'))
Traceback (most recent call last):
  File "/usr/itetnas04/data-scratch-01/dlim_03hs20/data/conda_envs/machineLearning/lib/python3.7/site-packages/urllib3/connection.py", line 160, in _new_conn
    (self._dns_host, self.port), self.timeout, **extra_kw
  File "/usr/itetnas04/data-scratch-01/dlim_03hs20/data/conda_envs/machineLearning/lib/python3.7/site-packages/urllib3/util/connection.py", line 84, in create_connection
    raise err
  File "/usr/itetnas04/data-scratch-01/dlim_03hs20/data/conda_envs/machineLearning/lib/python3.7/site-packages/urllib3/util/connection.py", line 74, in create_connection
    sock.connect(sa)
ConnectionRefusedError: [Errno 111] Connection refused

During handling of the above exception, another exception occurred:

Traceback (most recent call last):
  File "/usr/itetnas04/data-scratch-01/dlim_03hs20/data/conda_envs/machineLearning/lib/python3.7/site-packages/urllib3/connectionpool.py", line 677, in urlopen
    chunked=chunked,
  File "/usr/itetnas04/data-scratch-01/dlim_03hs20/data/conda_envs/machineLearning/lib/python3.7/site-packages/urllib3/connectionpool.py", line 392, in _make_request
    conn.request(method, url, **httplib_request_kw)
  File "/usr/itetnas04/data-scratch-01/dlim_03hs20/data/conda_envs/machineLearning/lib/python3.7/http/client.py", line 1277, in request
    self._send_request(method, url, body, headers, encode_chunked)
  File "/usr/itetnas04/data-scratch-01/dlim_03hs20/data/conda_envs/machineLearning/lib/python3.7/http/client.py", line 1323, in _send_request
    self.endheaders(body, encode_chunked=encode_chunked)
  File "/usr/itetnas04/data-scratch-01/dlim_03hs20/data/conda_envs/machineLearning/lib/python3.7/http/client.py", line 1272, in endheaders
    self._send_output(message_body, encode_chunked=encode_chunked)
  File "/usr/itetnas04/data-scratch-01/dlim_03hs20/data/conda_envs/machineLearning/lib/python3.7/http/client.py", line 1032, in _send_output
    self.send(msg)
  File "/usr/itetnas04/data-scratch-01/dlim_03hs20/data/conda_envs/machineLearning/lib/python3.7/http/client.py", line 972, in send
    self.connect()
  File "/usr/itetnas04/data-scratch-01/dlim_03hs20/data/conda_envs/machineLearning/lib/python3.7/site-packages/urllib3/connection.py", line 187, in connect
    conn = self._new_conn()
  File "/usr/itetnas04/data-scratch-01/dlim_03hs20/data/conda_envs/machineLearning/lib/python3.7/site-packages/urllib3/connection.py", line 172, in _new_conn
    self, "Failed to establish a new connection: %s" % e
urllib3.exceptions.NewConnectionError: <urllib3.connection.HTTPConnection object at 0x7fcd7a3ee290>: Failed to establish a new connection: [Errno 111] Connection refused

During handling of the above exception, another exception occurred:

Traceback (most recent call last):
  File "/usr/itetnas04/data-scratch-01/dlim_03hs20/data/conda_envs/machineLearning/lib/python3.7/site-packages/requests/adapters.py", line 449, in send
    timeout=timeout
  File "/usr/itetnas04/data-scratch-01/dlim_03hs20/data/conda_envs/machineLearning/lib/python3.7/site-packages/urllib3/connectionpool.py", line 727, in urlopen
    method, url, error=e, _pool=self, _stacktrace=sys.exc_info()[2]
  File "/usr/itetnas04/data-scratch-01/dlim_03hs20/data/conda_envs/machineLearning/lib/python3.7/site-packages/urllib3/util/retry.py", line 439, in increment
    raise MaxRetryError(_pool, url, error or ResponseError(cause))
urllib3.exceptions.MaxRetryError: HTTPConnectionPool(host='localhost', port=8097): Max retries exceeded with url: /events (Caused by NewConnectionError('<urllib3.connection.HTTPConnection object at 0x7fcd7a3ee290>: Failed to establish a new connection: [Errno 111] Connection refused'))

During handling of the above exception, another exception occurred:

Traceback (most recent call last):
  File "/usr/itetnas04/data-scratch-01/dlim_03hs20/data/conda_envs/machineLearning/lib/python3.7/site-packages/visdom/__init__.py", line 711, in _send
    data=json.dumps(msg),
  File "/usr/itetnas04/data-scratch-01/dlim_03hs20/data/conda_envs/machineLearning/lib/python3.7/site-packages/visdom/__init__.py", line 677, in _handle_post
    r = self.session.post(url, data=data)
  File "/usr/itetnas04/data-scratch-01/dlim_03hs20/data/conda_envs/machineLearning/lib/python3.7/site-packages/requests/sessions.py", line 578, in post
    return self.request('POST', url, data=data, json=json, **kwargs)
  File "/usr/itetnas04/data-scratch-01/dlim_03hs20/data/conda_envs/machineLearning/lib/python3.7/site-packages/requests/sessions.py", line 530, in request
    resp = self.send(prep, **send_kwargs)
  File "/usr/itetnas04/data-scratch-01/dlim_03hs20/data/conda_envs/machineLearning/lib/python3.7/site-packages/requests/sessions.py", line 643, in send
    r = adapter.send(request, **kwargs)
  File "/usr/itetnas04/data-scratch-01/dlim_03hs20/data/conda_envs/machineLearning/lib/python3.7/site-packages/requests/adapters.py", line 516, in send
    raise ConnectionError(e, request=request)
requests.exceptions.ConnectionError: HTTPConnectionPool(host='localhost', port=8097): Max retries exceeded with url: /events (Caused by NewConnectionError('<urllib3.connection.HTTPConnection object at 0x7fcd7a3ee290>: Failed to establish a new connection: [Errno 111] Connection refused'))
(epoch: 2, iters: 100, time: 0.056, data: 0.205) G_GAN: 1.671 G_L1: 32.225 D_real: 0.015 D_fake: 2.698 
Exception in user code:
------------------------------------------------------------
(epoch: 2, iters: 200, time: 0.059, data: 0.001) G_GAN: 3.224 G_L1: 27.835 D_real: 0.074 D_fake: 0.330 
Exception in user code:
------------------------------------------------------------
(epoch: 2, iters: 300, time: 0.060, data: 0.001) G_GAN: 3.802 G_L1: 35.893 D_real: 0.012 D_fake: 0.920 
Exception in user code:
------------------------------------------------------------
Exception in user code:
------------------------------------------------------------
Exception in user code:
------------------------------------------------------------
(epoch: 2, iters: 400, time: 0.273, data: 0.002) G_GAN: 2.653 G_L1: 32.819 D_real: 0.004 D_fake: 1.229 
Exception in user code:
------------------------------------------------------------
End of epoch 2 / 200 	 Time Taken: 20 sec
learning rate 0.0002000 -> 0.0002000
Traceback (most recent call last):
  File "/usr/itetnas04/data-scratch-01/dlim_03hs20/data/conda_envs/machineLearning/lib/python3.7/site-packages/urllib3/connection.py", line 160, in _new_conn
    (self._dns_host, self.port), self.timeout, **extra_kw
  File "/usr/itetnas04/data-scratch-01/dlim_03hs20/data/conda_envs/machineLearning/lib/python3.7/site-packages/urllib3/util/connection.py", line 84, in create_connection
    raise err
  File "/usr/itetnas04/data-scratch-01/dlim_03hs20/data/conda_envs/machineLearning/lib/python3.7/site-packages/urllib3/util/connection.py", line 74, in create_connection
    sock.connect(sa)
ConnectionRefusedError: [Errno 111] Connection refused

During handling of the above exception, another exception occurred:

Traceback (most recent call last):
  File "/usr/itetnas04/data-scratch-01/dlim_03hs20/data/conda_envs/machineLearning/lib/python3.7/site-packages/urllib3/connectionpool.py", line 677, in urlopen
    chunked=chunked,
  File "/usr/itetnas04/data-scratch-01/dlim_03hs20/data/conda_envs/machineLearning/lib/python3.7/site-packages/urllib3/connectionpool.py", line 392, in _make_request
    conn.request(method, url, **httplib_request_kw)
  File "/usr/itetnas04/data-scratch-01/dlim_03hs20/data/conda_envs/machineLearning/lib/python3.7/http/client.py", line 1277, in request
    self._send_request(method, url, body, headers, encode_chunked)
  File "/usr/itetnas04/data-scratch-01/dlim_03hs20/data/conda_envs/machineLearning/lib/python3.7/http/client.py", line 1323, in _send_request
    self.endheaders(body, encode_chunked=encode_chunked)
  File "/usr/itetnas04/data-scratch-01/dlim_03hs20/data/conda_envs/machineLearning/lib/python3.7/http/client.py", line 1272, in endheaders
    self._send_output(message_body, encode_chunked=encode_chunked)
  File "/usr/itetnas04/data-scratch-01/dlim_03hs20/data/conda_envs/machineLearning/lib/python3.7/http/client.py", line 1032, in _send_output
    self.send(msg)
  File "/usr/itetnas04/data-scratch-01/dlim_03hs20/data/conda_envs/machineLearning/lib/python3.7/http/client.py", line 972, in send
    self.connect()
  File "/usr/itetnas04/data-scratch-01/dlim_03hs20/data/conda_envs/machineLearning/lib/python3.7/site-packages/urllib3/connection.py", line 187, in connect
    conn = self._new_conn()
  File "/usr/itetnas04/data-scratch-01/dlim_03hs20/data/conda_envs/machineLearning/lib/python3.7/site-packages/urllib3/connection.py", line 172, in _new_conn
    self, "Failed to establish a new connection: %s" % e
urllib3.exceptions.NewConnectionError: <urllib3.connection.HTTPConnection object at 0x7fcd7a407190>: Failed to establish a new connection: [Errno 111] Connection refused

During handling of the above exception, another exception occurred:

Traceback (most recent call last):
  File "/usr/itetnas04/data-scratch-01/dlim_03hs20/data/conda_envs/machineLearning/lib/python3.7/site-packages/requests/adapters.py", line 449, in send
    timeout=timeout
  File "/usr/itetnas04/data-scratch-01/dlim_03hs20/data/conda_envs/machineLearning/lib/python3.7/site-packages/urllib3/connectionpool.py", line 727, in urlopen
    method, url, error=e, _pool=self, _stacktrace=sys.exc_info()[2]
  File "/usr/itetnas04/data-scratch-01/dlim_03hs20/data/conda_envs/machineLearning/lib/python3.7/site-packages/urllib3/util/retry.py", line 439, in increment
    raise MaxRetryError(_pool, url, error or ResponseError(cause))
urllib3.exceptions.MaxRetryError: HTTPConnectionPool(host='localhost', port=8097): Max retries exceeded with url: /events (Caused by NewConnectionError('<urllib3.connection.HTTPConnection object at 0x7fcd7a407190>: Failed to establish a new connection: [Errno 111] Connection refused'))

During handling of the above exception, another exception occurred:

Traceback (most recent call last):
  File "/usr/itetnas04/data-scratch-01/dlim_03hs20/data/conda_envs/machineLearning/lib/python3.7/site-packages/visdom/__init__.py", line 711, in _send
    data=json.dumps(msg),
  File "/usr/itetnas04/data-scratch-01/dlim_03hs20/data/conda_envs/machineLearning/lib/python3.7/site-packages/visdom/__init__.py", line 677, in _handle_post
    r = self.session.post(url, data=data)
  File "/usr/itetnas04/data-scratch-01/dlim_03hs20/data/conda_envs/machineLearning/lib/python3.7/site-packages/requests/sessions.py", line 578, in post
    return self.request('POST', url, data=data, json=json, **kwargs)
  File "/usr/itetnas04/data-scratch-01/dlim_03hs20/data/conda_envs/machineLearning/lib/python3.7/site-packages/requests/sessions.py", line 530, in request
    resp = self.send(prep, **send_kwargs)
  File "/usr/itetnas04/data-scratch-01/dlim_03hs20/data/conda_envs/machineLearning/lib/python3.7/site-packages/requests/sessions.py", line 643, in send
    r = adapter.send(request, **kwargs)
  File "/usr/itetnas04/data-scratch-01/dlim_03hs20/data/conda_envs/machineLearning/lib/python3.7/site-packages/requests/adapters.py", line 516, in send
    raise ConnectionError(e, request=request)
requests.exceptions.ConnectionError: HTTPConnectionPool(host='localhost', port=8097): Max retries exceeded with url: /events (Caused by NewConnectionError('<urllib3.connection.HTTPConnection object at 0x7fcd7a407190>: Failed to establish a new connection: [Errno 111] Connection refused'))
Traceback (most recent call last):
  File "/usr/itetnas04/data-scratch-01/dlim_03hs20/data/conda_envs/machineLearning/lib/python3.7/site-packages/urllib3/connection.py", line 160, in _new_conn
    (self._dns_host, self.port), self.timeout, **extra_kw
  File "/usr/itetnas04/data-scratch-01/dlim_03hs20/data/conda_envs/machineLearning/lib/python3.7/site-packages/urllib3/util/connection.py", line 84, in create_connection
    raise err
  File "/usr/itetnas04/data-scratch-01/dlim_03hs20/data/conda_envs/machineLearning/lib/python3.7/site-packages/urllib3/util/connection.py", line 74, in create_connection
    sock.connect(sa)
ConnectionRefusedError: [Errno 111] Connection refused

During handling of the above exception, another exception occurred:

Traceback (most recent call last):
  File "/usr/itetnas04/data-scratch-01/dlim_03hs20/data/conda_envs/machineLearning/lib/python3.7/site-packages/urllib3/connectionpool.py", line 677, in urlopen
    chunked=chunked,
  File "/usr/itetnas04/data-scratch-01/dlim_03hs20/data/conda_envs/machineLearning/lib/python3.7/site-packages/urllib3/connectionpool.py", line 392, in _make_request
    conn.request(method, url, **httplib_request_kw)
  File "/usr/itetnas04/data-scratch-01/dlim_03hs20/data/conda_envs/machineLearning/lib/python3.7/http/client.py", line 1277, in request
    self._send_request(method, url, body, headers, encode_chunked)
  File "/usr/itetnas04/data-scratch-01/dlim_03hs20/data/conda_envs/machineLearning/lib/python3.7/http/client.py", line 1323, in _send_request
    self.endheaders(body, encode_chunked=encode_chunked)
  File "/usr/itetnas04/data-scratch-01/dlim_03hs20/data/conda_envs/machineLearning/lib/python3.7/http/client.py", line 1272, in endheaders
    self._send_output(message_body, encode_chunked=encode_chunked)
  File "/usr/itetnas04/data-scratch-01/dlim_03hs20/data/conda_envs/machineLearning/lib/python3.7/http/client.py", line 1032, in _send_output
    self.send(msg)
  File "/usr/itetnas04/data-scratch-01/dlim_03hs20/data/conda_envs/machineLearning/lib/python3.7/http/client.py", line 972, in send
    self.connect()
  File "/usr/itetnas04/data-scratch-01/dlim_03hs20/data/conda_envs/machineLearning/lib/python3.7/site-packages/urllib3/connection.py", line 187, in connect
    conn = self._new_conn()
  File "/usr/itetnas04/data-scratch-01/dlim_03hs20/data/conda_envs/machineLearning/lib/python3.7/site-packages/urllib3/connection.py", line 172, in _new_conn
    self, "Failed to establish a new connection: %s" % e
urllib3.exceptions.NewConnectionError: <urllib3.connection.HTTPConnection object at 0x7fcd7a404bd0>: Failed to establish a new connection: [Errno 111] Connection refused

During handling of the above exception, another exception occurred:

Traceback (most recent call last):
  File "/usr/itetnas04/data-scratch-01/dlim_03hs20/data/conda_envs/machineLearning/lib/python3.7/site-packages/requests/adapters.py", line 449, in send
    timeout=timeout
  File "/usr/itetnas04/data-scratch-01/dlim_03hs20/data/conda_envs/machineLearning/lib/python3.7/site-packages/urllib3/connectionpool.py", line 727, in urlopen
    method, url, error=e, _pool=self, _stacktrace=sys.exc_info()[2]
  File "/usr/itetnas04/data-scratch-01/dlim_03hs20/data/conda_envs/machineLearning/lib/python3.7/site-packages/urllib3/util/retry.py", line 439, in increment
    raise MaxRetryError(_pool, url, error or ResponseError(cause))
urllib3.exceptions.MaxRetryError: HTTPConnectionPool(host='localhost', port=8097): Max retries exceeded with url: /events (Caused by NewConnectionError('<urllib3.connection.HTTPConnection object at 0x7fcd7a404bd0>: Failed to establish a new connection: [Errno 111] Connection refused'))

During handling of the above exception, another exception occurred:

Traceback (most recent call last):
  File "/usr/itetnas04/data-scratch-01/dlim_03hs20/data/conda_envs/machineLearning/lib/python3.7/site-packages/visdom/__init__.py", line 711, in _send
    data=json.dumps(msg),
  File "/usr/itetnas04/data-scratch-01/dlim_03hs20/data/conda_envs/machineLearning/lib/python3.7/site-packages/visdom/__init__.py", line 677, in _handle_post
    r = self.session.post(url, data=data)
  File "/usr/itetnas04/data-scratch-01/dlim_03hs20/data/conda_envs/machineLearning/lib/python3.7/site-packages/requests/sessions.py", line 578, in post
    return self.request('POST', url, data=data, json=json, **kwargs)
  File "/usr/itetnas04/data-scratch-01/dlim_03hs20/data/conda_envs/machineLearning/lib/python3.7/site-packages/requests/sessions.py", line 530, in request
    resp = self.send(prep, **send_kwargs)
  File "/usr/itetnas04/data-scratch-01/dlim_03hs20/data/conda_envs/machineLearning/lib/python3.7/site-packages/requests/sessions.py", line 643, in send
    r = adapter.send(request, **kwargs)
  File "/usr/itetnas04/data-scratch-01/dlim_03hs20/data/conda_envs/machineLearning/lib/python3.7/site-packages/requests/adapters.py", line 516, in send
    raise ConnectionError(e, request=request)
requests.exceptions.ConnectionError: HTTPConnectionPool(host='localhost', port=8097): Max retries exceeded with url: /events (Caused by NewConnectionError('<urllib3.connection.HTTPConnection object at 0x7fcd7a404bd0>: Failed to establish a new connection: [Errno 111] Connection refused'))
Traceback (most recent call last):
  File "/usr/itetnas04/data-scratch-01/dlim_03hs20/data/conda_envs/machineLearning/lib/python3.7/site-packages/urllib3/connection.py", line 160, in _new_conn
    (self._dns_host, self.port), self.timeout, **extra_kw
  File "/usr/itetnas04/data-scratch-01/dlim_03hs20/data/conda_envs/machineLearning/lib/python3.7/site-packages/urllib3/util/connection.py", line 84, in create_connection
    raise err
  File "/usr/itetnas04/data-scratch-01/dlim_03hs20/data/conda_envs/machineLearning/lib/python3.7/site-packages/urllib3/util/connection.py", line 74, in create_connection
    sock.connect(sa)
ConnectionRefusedError: [Errno 111] Connection refused

During handling of the above exception, another exception occurred:

Traceback (most recent call last):
  File "/usr/itetnas04/data-scratch-01/dlim_03hs20/data/conda_envs/machineLearning/lib/python3.7/site-packages/urllib3/connectionpool.py", line 677, in urlopen
    chunked=chunked,
  File "/usr/itetnas04/data-scratch-01/dlim_03hs20/data/conda_envs/machineLearning/lib/python3.7/site-packages/urllib3/connectionpool.py", line 392, in _make_request
    conn.request(method, url, **httplib_request_kw)
  File "/usr/itetnas04/data-scratch-01/dlim_03hs20/data/conda_envs/machineLearning/lib/python3.7/http/client.py", line 1277, in request
    self._send_request(method, url, body, headers, encode_chunked)
  File "/usr/itetnas04/data-scratch-01/dlim_03hs20/data/conda_envs/machineLearning/lib/python3.7/http/client.py", line 1323, in _send_request
    self.endheaders(body, encode_chunked=encode_chunked)
  File "/usr/itetnas04/data-scratch-01/dlim_03hs20/data/conda_envs/machineLearning/lib/python3.7/http/client.py", line 1272, in endheaders
    self._send_output(message_body, encode_chunked=encode_chunked)
  File "/usr/itetnas04/data-scratch-01/dlim_03hs20/data/conda_envs/machineLearning/lib/python3.7/http/client.py", line 1032, in _send_output
    self.send(msg)
  File "/usr/itetnas04/data-scratch-01/dlim_03hs20/data/conda_envs/machineLearning/lib/python3.7/http/client.py", line 972, in send
    self.connect()
  File "/usr/itetnas04/data-scratch-01/dlim_03hs20/data/conda_envs/machineLearning/lib/python3.7/site-packages/urllib3/connection.py", line 187, in connect
    conn = self._new_conn()
  File "/usr/itetnas04/data-scratch-01/dlim_03hs20/data/conda_envs/machineLearning/lib/python3.7/site-packages/urllib3/connection.py", line 172, in _new_conn
    self, "Failed to establish a new connection: %s" % e
urllib3.exceptions.NewConnectionError: <urllib3.connection.HTTPConnection object at 0x7fcd7a403e10>: Failed to establish a new connection: [Errno 111] Connection refused

During handling of the above exception, another exception occurred:

Traceback (most recent call last):
  File "/usr/itetnas04/data-scratch-01/dlim_03hs20/data/conda_envs/machineLearning/lib/python3.7/site-packages/requests/adapters.py", line 449, in send
    timeout=timeout
  File "/usr/itetnas04/data-scratch-01/dlim_03hs20/data/conda_envs/machineLearning/lib/python3.7/site-packages/urllib3/connectionpool.py", line 727, in urlopen
    method, url, error=e, _pool=self, _stacktrace=sys.exc_info()[2]
  File "/usr/itetnas04/data-scratch-01/dlim_03hs20/data/conda_envs/machineLearning/lib/python3.7/site-packages/urllib3/util/retry.py", line 439, in increment
    raise MaxRetryError(_pool, url, error or ResponseError(cause))
urllib3.exceptions.MaxRetryError: HTTPConnectionPool(host='localhost', port=8097): Max retries exceeded with url: /events (Caused by NewConnectionError('<urllib3.connection.HTTPConnection object at 0x7fcd7a403e10>: Failed to establish a new connection: [Errno 111] Connection refused'))

During handling of the above exception, another exception occurred:

Traceback (most recent call last):
  File "/usr/itetnas04/data-scratch-01/dlim_03hs20/data/conda_envs/machineLearning/lib/python3.7/site-packages/visdom/__init__.py", line 711, in _send
    data=json.dumps(msg),
  File "/usr/itetnas04/data-scratch-01/dlim_03hs20/data/conda_envs/machineLearning/lib/python3.7/site-packages/visdom/__init__.py", line 677, in _handle_post
    r = self.session.post(url, data=data)
  File "/usr/itetnas04/data-scratch-01/dlim_03hs20/data/conda_envs/machineLearning/lib/python3.7/site-packages/requests/sessions.py", line 578, in post
    return self.request('POST', url, data=data, json=json, **kwargs)
  File "/usr/itetnas04/data-scratch-01/dlim_03hs20/data/conda_envs/machineLearning/lib/python3.7/site-packages/requests/sessions.py", line 530, in request
    resp = self.send(prep, **send_kwargs)
  File "/usr/itetnas04/data-scratch-01/dlim_03hs20/data/conda_envs/machineLearning/lib/python3.7/site-packages/requests/sessions.py", line 643, in send
    r = adapter.send(request, **kwargs)
  File "/usr/itetnas04/data-scratch-01/dlim_03hs20/data/conda_envs/machineLearning/lib/python3.7/site-packages/requests/adapters.py", line 516, in send
    raise ConnectionError(e, request=request)
requests.exceptions.ConnectionError: HTTPConnectionPool(host='localhost', port=8097): Max retries exceeded with url: /events (Caused by NewConnectionError('<urllib3.connection.HTTPConnection object at 0x7fcd7a403e10>: Failed to establish a new connection: [Errno 111] Connection refused'))
Traceback (most recent call last):
  File "/usr/itetnas04/data-scratch-01/dlim_03hs20/data/conda_envs/machineLearning/lib/python3.7/site-packages/urllib3/connection.py", line 160, in _new_conn
    (self._dns_host, self.port), self.timeout, **extra_kw
  File "/usr/itetnas04/data-scratch-01/dlim_03hs20/data/conda_envs/machineLearning/lib/python3.7/site-packages/urllib3/util/connection.py", line 84, in create_connection
    raise err
  File "/usr/itetnas04/data-scratch-01/dlim_03hs20/data/conda_envs/machineLearning/lib/python3.7/site-packages/urllib3/util/connection.py", line 74, in create_connection
    sock.connect(sa)
ConnectionRefusedError: [Errno 111] Connection refused

During handling of the above exception, another exception occurred:

Traceback (most recent call last):
  File "/usr/itetnas04/data-scratch-01/dlim_03hs20/data/conda_envs/machineLearning/lib/python3.7/site-packages/urllib3/connectionpool.py", line 677, in urlopen
    chunked=chunked,
  File "/usr/itetnas04/data-scratch-01/dlim_03hs20/data/conda_envs/machineLearning/lib/python3.7/site-packages/urllib3/connectionpool.py", line 392, in _make_request
    conn.request(method, url, **httplib_request_kw)
  File "/usr/itetnas04/data-scratch-01/dlim_03hs20/data/conda_envs/machineLearning/lib/python3.7/http/client.py", line 1277, in request
    self._send_request(method, url, body, headers, encode_chunked)
  File "/usr/itetnas04/data-scratch-01/dlim_03hs20/data/conda_envs/machineLearning/lib/python3.7/http/client.py", line 1323, in _send_request
    self.endheaders(body, encode_chunked=encode_chunked)
  File "/usr/itetnas04/data-scratch-01/dlim_03hs20/data/conda_envs/machineLearning/lib/python3.7/http/client.py", line 1272, in endheaders
    self._send_output(message_body, encode_chunked=encode_chunked)
  File "/usr/itetnas04/data-scratch-01/dlim_03hs20/data/conda_envs/machineLearning/lib/python3.7/http/client.py", line 1032, in _send_output
    self.send(msg)
  File "/usr/itetnas04/data-scratch-01/dlim_03hs20/data/conda_envs/machineLearning/lib/python3.7/http/client.py", line 972, in send
    self.connect()
  File "/usr/itetnas04/data-scratch-01/dlim_03hs20/data/conda_envs/machineLearning/lib/python3.7/site-packages/urllib3/connection.py", line 187, in connect
    conn = self._new_conn()
  File "/usr/itetnas04/data-scratch-01/dlim_03hs20/data/conda_envs/machineLearning/lib/python3.7/site-packages/urllib3/connection.py", line 172, in _new_conn
    self, "Failed to establish a new connection: %s" % e
urllib3.exceptions.NewConnectionError: <urllib3.connection.HTTPConnection object at 0x7fcd7a4100d0>: Failed to establish a new connection: [Errno 111] Connection refused

During handling of the above exception, another exception occurred:

Traceback (most recent call last):
  File "/usr/itetnas04/data-scratch-01/dlim_03hs20/data/conda_envs/machineLearning/lib/python3.7/site-packages/requests/adapters.py", line 449, in send
    timeout=timeout
  File "/usr/itetnas04/data-scratch-01/dlim_03hs20/data/conda_envs/machineLearning/lib/python3.7/site-packages/urllib3/connectionpool.py", line 727, in urlopen
    method, url, error=e, _pool=self, _stacktrace=sys.exc_info()[2]
  File "/usr/itetnas04/data-scratch-01/dlim_03hs20/data/conda_envs/machineLearning/lib/python3.7/site-packages/urllib3/util/retry.py", line 439, in increment
    raise MaxRetryError(_pool, url, error or ResponseError(cause))
urllib3.exceptions.MaxRetryError: HTTPConnectionPool(host='localhost', port=8097): Max retries exceeded with url: /events (Caused by NewConnectionError('<urllib3.connection.HTTPConnection object at 0x7fcd7a4100d0>: Failed to establish a new connection: [Errno 111] Connection refused'))

During handling of the above exception, another exception occurred:

Traceback (most recent call last):
  File "/usr/itetnas04/data-scratch-01/dlim_03hs20/data/conda_envs/machineLearning/lib/python3.7/site-packages/visdom/__init__.py", line 711, in _send
    data=json.dumps(msg),
  File "/usr/itetnas04/data-scratch-01/dlim_03hs20/data/conda_envs/machineLearning/lib/python3.7/site-packages/visdom/__init__.py", line 677, in _handle_post
    r = self.session.post(url, data=data)
  File "/usr/itetnas04/data-scratch-01/dlim_03hs20/data/conda_envs/machineLearning/lib/python3.7/site-packages/requests/sessions.py", line 578, in post
    return self.request('POST', url, data=data, json=json, **kwargs)
  File "/usr/itetnas04/data-scratch-01/dlim_03hs20/data/conda_envs/machineLearning/lib/python3.7/site-packages/requests/sessions.py", line 530, in request
    resp = self.send(prep, **send_kwargs)
  File "/usr/itetnas04/data-scratch-01/dlim_03hs20/data/conda_envs/machineLearning/lib/python3.7/site-packages/requests/sessions.py", line 643, in send
    r = adapter.send(request, **kwargs)
  File "/usr/itetnas04/data-scratch-01/dlim_03hs20/data/conda_envs/machineLearning/lib/python3.7/site-packages/requests/adapters.py", line 516, in send
    raise ConnectionError(e, request=request)
requests.exceptions.ConnectionError: HTTPConnectionPool(host='localhost', port=8097): Max retries exceeded with url: /events (Caused by NewConnectionError('<urllib3.connection.HTTPConnection object at 0x7fcd7a4100d0>: Failed to establish a new connection: [Errno 111] Connection refused'))
Traceback (most recent call last):
  File "/usr/itetnas04/data-scratch-01/dlim_03hs20/data/conda_envs/machineLearning/lib/python3.7/site-packages/urllib3/connection.py", line 160, in _new_conn
    (self._dns_host, self.port), self.timeout, **extra_kw
  File "/usr/itetnas04/data-scratch-01/dlim_03hs20/data/conda_envs/machineLearning/lib/python3.7/site-packages/urllib3/util/connection.py", line 84, in create_connection
    raise err
  File "/usr/itetnas04/data-scratch-01/dlim_03hs20/data/conda_envs/machineLearning/lib/python3.7/site-packages/urllib3/util/connection.py", line 74, in create_connection
    sock.connect(sa)
ConnectionRefusedError: [Errno 111] Connection refused

During handling of the above exception, another exception occurred:

Traceback (most recent call last):
  File "/usr/itetnas04/data-scratch-01/dlim_03hs20/data/conda_envs/machineLearning/lib/python3.7/site-packages/urllib3/connectionpool.py", line 677, in urlopen
    chunked=chunked,
  File "/usr/itetnas04/data-scratch-01/dlim_03hs20/data/conda_envs/machineLearning/lib/python3.7/site-packages/urllib3/connectionpool.py", line 392, in _make_request
    conn.request(method, url, **httplib_request_kw)
  File "/usr/itetnas04/data-scratch-01/dlim_03hs20/data/conda_envs/machineLearning/lib/python3.7/http/client.py", line 1277, in request
    self._send_request(method, url, body, headers, encode_chunked)
  File "/usr/itetnas04/data-scratch-01/dlim_03hs20/data/conda_envs/machineLearning/lib/python3.7/http/client.py", line 1323, in _send_request
    self.endheaders(body, encode_chunked=encode_chunked)
  File "/usr/itetnas04/data-scratch-01/dlim_03hs20/data/conda_envs/machineLearning/lib/python3.7/http/client.py", line 1272, in endheaders
    self._send_output(message_body, encode_chunked=encode_chunked)
  File "/usr/itetnas04/data-scratch-01/dlim_03hs20/data/conda_envs/machineLearning/lib/python3.7/http/client.py", line 1032, in _send_output
    self.send(msg)
  File "/usr/itetnas04/data-scratch-01/dlim_03hs20/data/conda_envs/machineLearning/lib/python3.7/http/client.py", line 972, in send
    self.connect()
  File "/usr/itetnas04/data-scratch-01/dlim_03hs20/data/conda_envs/machineLearning/lib/python3.7/site-packages/urllib3/connection.py", line 187, in connect
    conn = self._new_conn()
  File "/usr/itetnas04/data-scratch-01/dlim_03hs20/data/conda_envs/machineLearning/lib/python3.7/site-packages/urllib3/connection.py", line 172, in _new_conn
    self, "Failed to establish a new connection: %s" % e
urllib3.exceptions.NewConnectionError: <urllib3.connection.HTTPConnection object at 0x7fcd7a410750>: Failed to establish a new connection: [Errno 111] Connection refused

During handling of the above exception, another exception occurred:

Traceback (most recent call last):
  File "/usr/itetnas04/data-scratch-01/dlim_03hs20/data/conda_envs/machineLearning/lib/python3.7/site-packages/requests/adapters.py", line 449, in send
    timeout=timeout
  File "/usr/itetnas04/data-scratch-01/dlim_03hs20/data/conda_envs/machineLearning/lib/python3.7/site-packages/urllib3/connectionpool.py", line 727, in urlopen
    method, url, error=e, _pool=self, _stacktrace=sys.exc_info()[2]
  File "/usr/itetnas04/data-scratch-01/dlim_03hs20/data/conda_envs/machineLearning/lib/python3.7/site-packages/urllib3/util/retry.py", line 439, in increment
    raise MaxRetryError(_pool, url, error or ResponseError(cause))
urllib3.exceptions.MaxRetryError: HTTPConnectionPool(host='localhost', port=8097): Max retries exceeded with url: /events (Caused by NewConnectionError('<urllib3.connection.HTTPConnection object at 0x7fcd7a410750>: Failed to establish a new connection: [Errno 111] Connection refused'))

During handling of the above exception, another exception occurred:

Traceback (most recent call last):
  File "/usr/itetnas04/data-scratch-01/dlim_03hs20/data/conda_envs/machineLearning/lib/python3.7/site-packages/visdom/__init__.py", line 711, in _send
    data=json.dumps(msg),
  File "/usr/itetnas04/data-scratch-01/dlim_03hs20/data/conda_envs/machineLearning/lib/python3.7/site-packages/visdom/__init__.py", line 677, in _handle_post
    r = self.session.post(url, data=data)
  File "/usr/itetnas04/data-scratch-01/dlim_03hs20/data/conda_envs/machineLearning/lib/python3.7/site-packages/requests/sessions.py", line 578, in post
    return self.request('POST', url, data=data, json=json, **kwargs)
  File "/usr/itetnas04/data-scratch-01/dlim_03hs20/data/conda_envs/machineLearning/lib/python3.7/site-packages/requests/sessions.py", line 530, in request
    resp = self.send(prep, **send_kwargs)
  File "/usr/itetnas04/data-scratch-01/dlim_03hs20/data/conda_envs/machineLearning/lib/python3.7/site-packages/requests/sessions.py", line 643, in send
    r = adapter.send(request, **kwargs)
  File "/usr/itetnas04/data-scratch-01/dlim_03hs20/data/conda_envs/machineLearning/lib/python3.7/site-packages/requests/adapters.py", line 516, in send
    raise ConnectionError(e, request=request)
requests.exceptions.ConnectionError: HTTPConnectionPool(host='localhost', port=8097): Max retries exceeded with url: /events (Caused by NewConnectionError('<urllib3.connection.HTTPConnection object at 0x7fcd7a410750>: Failed to establish a new connection: [Errno 111] Connection refused'))
Traceback (most recent call last):
  File "/usr/itetnas04/data-scratch-01/dlim_03hs20/data/conda_envs/machineLearning/lib/python3.7/site-packages/urllib3/connection.py", line 160, in _new_conn
    (self._dns_host, self.port), self.timeout, **extra_kw
  File "/usr/itetnas04/data-scratch-01/dlim_03hs20/data/conda_envs/machineLearning/lib/python3.7/site-packages/urllib3/util/connection.py", line 84, in create_connection
    raise err
  File "/usr/itetnas04/data-scratch-01/dlim_03hs20/data/conda_envs/machineLearning/lib/python3.7/site-packages/urllib3/util/connection.py", line 74, in create_connection
    sock.connect(sa)
ConnectionRefusedError: [Errno 111] Connection refused

During handling of the above exception, another exception occurred:

Traceback (most recent call last):
  File "/usr/itetnas04/data-scratch-01/dlim_03hs20/data/conda_envs/machineLearning/lib/python3.7/site-packages/urllib3/connectionpool.py", line 677, in urlopen
    chunked=chunked,
  File "/usr/itetnas04/data-scratch-01/dlim_03hs20/data/conda_envs/machineLearning/lib/python3.7/site-packages/urllib3/connectionpool.py", line 392, in _make_request
    conn.request(method, url, **httplib_request_kw)
  File "/usr/itetnas04/data-scratch-01/dlim_03hs20/data/conda_envs/machineLearning/lib/python3.7/http/client.py", line 1277, in request
    self._send_request(method, url, body, headers, encode_chunked)
  File "/usr/itetnas04/data-scratch-01/dlim_03hs20/data/conda_envs/machineLearning/lib/python3.7/http/client.py", line 1323, in _send_request
    self.endheaders(body, encode_chunked=encode_chunked)
  File "/usr/itetnas04/data-scratch-01/dlim_03hs20/data/conda_envs/machineLearning/lib/python3.7/http/client.py", line 1272, in endheaders
    self._send_output(message_body, encode_chunked=encode_chunked)
  File "/usr/itetnas04/data-scratch-01/dlim_03hs20/data/conda_envs/machineLearning/lib/python3.7/http/client.py", line 1032, in _send_output
    self.send(msg)
  File "/usr/itetnas04/data-scratch-01/dlim_03hs20/data/conda_envs/machineLearning/lib/python3.7/http/client.py", line 972, in send
    self.connect()
  File "/usr/itetnas04/data-scratch-01/dlim_03hs20/data/conda_envs/machineLearning/lib/python3.7/site-packages/urllib3/connection.py", line 187, in connect
    conn = self._new_conn()
  File "/usr/itetnas04/data-scratch-01/dlim_03hs20/data/conda_envs/machineLearning/lib/python3.7/site-packages/urllib3/connection.py", line 172, in _new_conn
    self, "Failed to establish a new connection: %s" % e
urllib3.exceptions.NewConnectionError: <urllib3.connection.HTTPConnection object at 0x7fcd7a403150>: Failed to establish a new connection: [Errno 111] Connection refused

During handling of the above exception, another exception occurred:

Traceback (most recent call last):
  File "/usr/itetnas04/data-scratch-01/dlim_03hs20/data/conda_envs/machineLearning/lib/python3.7/site-packages/requests/adapters.py", line 449, in send
    timeout=timeout
  File "/usr/itetnas04/data-scratch-01/dlim_03hs20/data/conda_envs/machineLearning/lib/python3.7/site-packages/urllib3/connectionpool.py", line 727, in urlopen
    method, url, error=e, _pool=self, _stacktrace=sys.exc_info()[2]
  File "/usr/itetnas04/data-scratch-01/dlim_03hs20/data/conda_envs/machineLearning/lib/python3.7/site-packages/urllib3/util/retry.py", line 439, in increment
    raise MaxRetryError(_pool, url, error or ResponseError(cause))
urllib3.exceptions.MaxRetryError: HTTPConnectionPool(host='localhost', port=8097): Max retries exceeded with url: /events (Caused by NewConnectionError('<urllib3.connection.HTTPConnection object at 0x7fcd7a403150>: Failed to establish a new connection: [Errno 111] Connection refused'))

During handling of the above exception, another exception occurred:

Traceback (most recent call last):
  File "/usr/itetnas04/data-scratch-01/dlim_03hs20/data/conda_envs/machineLearning/lib/python3.7/site-packages/visdom/__init__.py", line 711, in _send
    data=json.dumps(msg),
  File "/usr/itetnas04/data-scratch-01/dlim_03hs20/data/conda_envs/machineLearning/lib/python3.7/site-packages/visdom/__init__.py", line 677, in _handle_post
    r = self.session.post(url, data=data)
  File "/usr/itetnas04/data-scratch-01/dlim_03hs20/data/conda_envs/machineLearning/lib/python3.7/site-packages/requests/sessions.py", line 578, in post
    return self.request('POST', url, data=data, json=json, **kwargs)
  File "/usr/itetnas04/data-scratch-01/dlim_03hs20/data/conda_envs/machineLearning/lib/python3.7/site-packages/requests/sessions.py", line 530, in request
    resp = self.send(prep, **send_kwargs)
  File "/usr/itetnas04/data-scratch-01/dlim_03hs20/data/conda_envs/machineLearning/lib/python3.7/site-packages/requests/sessions.py", line 643, in send
    r = adapter.send(request, **kwargs)
  File "/usr/itetnas04/data-scratch-01/dlim_03hs20/data/conda_envs/machineLearning/lib/python3.7/site-packages/requests/adapters.py", line 516, in send
    raise ConnectionError(e, request=request)
requests.exceptions.ConnectionError: HTTPConnectionPool(host='localhost', port=8097): Max retries exceeded with url: /events (Caused by NewConnectionError('<urllib3.connection.HTTPConnection object at 0x7fcd7a403150>: Failed to establish a new connection: [Errno 111] Connection refused'))
(epoch: 3, iters: 100, time: 0.058, data: 0.203) G_GAN: 3.717 G_L1: 34.051 D_real: 0.017 D_fake: 0.055 
Exception in user code:
------------------------------------------------------------
(epoch: 3, iters: 200, time: 0.056, data: 0.002) G_GAN: 1.999 G_L1: 30.892 D_real: 0.986 D_fake: 0.022 
Exception in user code:
------------------------------------------------------------
(epoch: 3, iters: 300, time: 0.057, data: 0.002) G_GAN: 4.998 G_L1: 56.606 D_real: 0.034 D_fake: 0.011 
Exception in user code:
------------------------------------------------------------
Exception in user code:
------------------------------------------------------------
Exception in user code:
------------------------------------------------------------
(epoch: 3, iters: 400, time: 0.273, data: 0.002) G_GAN: 2.976 G_L1: 39.560 D_real: 0.029 D_fake: 0.085 
Exception in user code:
------------------------------------------------------------
End of epoch 3 / 200 	 Time Taken: 20 sec
learning rate 0.0002000 -> 0.0002000
Traceback (most recent call last):
  File "/usr/itetnas04/data-scratch-01/dlim_03hs20/data/conda_envs/machineLearning/lib/python3.7/site-packages/urllib3/connection.py", line 160, in _new_conn
    (self._dns_host, self.port), self.timeout, **extra_kw
  File "/usr/itetnas04/data-scratch-01/dlim_03hs20/data/conda_envs/machineLearning/lib/python3.7/site-packages/urllib3/util/connection.py", line 84, in create_connection
    raise err
  File "/usr/itetnas04/data-scratch-01/dlim_03hs20/data/conda_envs/machineLearning/lib/python3.7/site-packages/urllib3/util/connection.py", line 74, in create_connection
    sock.connect(sa)
ConnectionRefusedError: [Errno 111] Connection refused

During handling of the above exception, another exception occurred:

Traceback (most recent call last):
  File "/usr/itetnas04/data-scratch-01/dlim_03hs20/data/conda_envs/machineLearning/lib/python3.7/site-packages/urllib3/connectionpool.py", line 677, in urlopen
    chunked=chunked,
  File "/usr/itetnas04/data-scratch-01/dlim_03hs20/data/conda_envs/machineLearning/lib/python3.7/site-packages/urllib3/connectionpool.py", line 392, in _make_request
    conn.request(method, url, **httplib_request_kw)
  File "/usr/itetnas04/data-scratch-01/dlim_03hs20/data/conda_envs/machineLearning/lib/python3.7/http/client.py", line 1277, in request
    self._send_request(method, url, body, headers, encode_chunked)
  File "/usr/itetnas04/data-scratch-01/dlim_03hs20/data/conda_envs/machineLearning/lib/python3.7/http/client.py", line 1323, in _send_request
    self.endheaders(body, encode_chunked=encode_chunked)
  File "/usr/itetnas04/data-scratch-01/dlim_03hs20/data/conda_envs/machineLearning/lib/python3.7/http/client.py", line 1272, in endheaders
    self._send_output(message_body, encode_chunked=encode_chunked)
  File "/usr/itetnas04/data-scratch-01/dlim_03hs20/data/conda_envs/machineLearning/lib/python3.7/http/client.py", line 1032, in _send_output
    self.send(msg)
  File "/usr/itetnas04/data-scratch-01/dlim_03hs20/data/conda_envs/machineLearning/lib/python3.7/http/client.py", line 972, in send
    self.connect()
  File "/usr/itetnas04/data-scratch-01/dlim_03hs20/data/conda_envs/machineLearning/lib/python3.7/site-packages/urllib3/connection.py", line 187, in connect
    conn = self._new_conn()
  File "/usr/itetnas04/data-scratch-01/dlim_03hs20/data/conda_envs/machineLearning/lib/python3.7/site-packages/urllib3/connection.py", line 172, in _new_conn
    self, "Failed to establish a new connection: %s" % e
urllib3.exceptions.NewConnectionError: <urllib3.connection.HTTPConnection object at 0x7fcd7a410d50>: Failed to establish a new connection: [Errno 111] Connection refused

During handling of the above exception, another exception occurred:

Traceback (most recent call last):
  File "/usr/itetnas04/data-scratch-01/dlim_03hs20/data/conda_envs/machineLearning/lib/python3.7/site-packages/requests/adapters.py", line 449, in send
    timeout=timeout
  File "/usr/itetnas04/data-scratch-01/dlim_03hs20/data/conda_envs/machineLearning/lib/python3.7/site-packages/urllib3/connectionpool.py", line 727, in urlopen
    method, url, error=e, _pool=self, _stacktrace=sys.exc_info()[2]
  File "/usr/itetnas04/data-scratch-01/dlim_03hs20/data/conda_envs/machineLearning/lib/python3.7/site-packages/urllib3/util/retry.py", line 439, in increment
    raise MaxRetryError(_pool, url, error or ResponseError(cause))
urllib3.exceptions.MaxRetryError: HTTPConnectionPool(host='localhost', port=8097): Max retries exceeded with url: /events (Caused by NewConnectionError('<urllib3.connection.HTTPConnection object at 0x7fcd7a410d50>: Failed to establish a new connection: [Errno 111] Connection refused'))

During handling of the above exception, another exception occurred:

Traceback (most recent call last):
  File "/usr/itetnas04/data-scratch-01/dlim_03hs20/data/conda_envs/machineLearning/lib/python3.7/site-packages/visdom/__init__.py", line 711, in _send
    data=json.dumps(msg),
  File "/usr/itetnas04/data-scratch-01/dlim_03hs20/data/conda_envs/machineLearning/lib/python3.7/site-packages/visdom/__init__.py", line 677, in _handle_post
    r = self.session.post(url, data=data)
  File "/usr/itetnas04/data-scratch-01/dlim_03hs20/data/conda_envs/machineLearning/lib/python3.7/site-packages/requests/sessions.py", line 578, in post
    return self.request('POST', url, data=data, json=json, **kwargs)
  File "/usr/itetnas04/data-scratch-01/dlim_03hs20/data/conda_envs/machineLearning/lib/python3.7/site-packages/requests/sessions.py", line 530, in request
    resp = self.send(prep, **send_kwargs)
  File "/usr/itetnas04/data-scratch-01/dlim_03hs20/data/conda_envs/machineLearning/lib/python3.7/site-packages/requests/sessions.py", line 643, in send
    r = adapter.send(request, **kwargs)
  File "/usr/itetnas04/data-scratch-01/dlim_03hs20/data/conda_envs/machineLearning/lib/python3.7/site-packages/requests/adapters.py", line 516, in send
    raise ConnectionError(e, request=request)
requests.exceptions.ConnectionError: HTTPConnectionPool(host='localhost', port=8097): Max retries exceeded with url: /events (Caused by NewConnectionError('<urllib3.connection.HTTPConnection object at 0x7fcd7a410d50>: Failed to establish a new connection: [Errno 111] Connection refused'))
Traceback (most recent call last):
  File "/usr/itetnas04/data-scratch-01/dlim_03hs20/data/conda_envs/machineLearning/lib/python3.7/site-packages/urllib3/connection.py", line 160, in _new_conn
    (self._dns_host, self.port), self.timeout, **extra_kw
  File "/usr/itetnas04/data-scratch-01/dlim_03hs20/data/conda_envs/machineLearning/lib/python3.7/site-packages/urllib3/util/connection.py", line 84, in create_connection
    raise err
  File "/usr/itetnas04/data-scratch-01/dlim_03hs20/data/conda_envs/machineLearning/lib/python3.7/site-packages/urllib3/util/connection.py", line 74, in create_connection
    sock.connect(sa)
ConnectionRefusedError: [Errno 111] Connection refused

During handling of the above exception, another exception occurred:

Traceback (most recent call last):
  File "/usr/itetnas04/data-scratch-01/dlim_03hs20/data/conda_envs/machineLearning/lib/python3.7/site-packages/urllib3/connectionpool.py", line 677, in urlopen
    chunked=chunked,
  File "/usr/itetnas04/data-scratch-01/dlim_03hs20/data/conda_envs/machineLearning/lib/python3.7/site-packages/urllib3/connectionpool.py", line 392, in _make_request
    conn.request(method, url, **httplib_request_kw)
  File "/usr/itetnas04/data-scratch-01/dlim_03hs20/data/conda_envs/machineLearning/lib/python3.7/http/client.py", line 1277, in request
    self._send_request(method, url, body, headers, encode_chunked)
  File "/usr/itetnas04/data-scratch-01/dlim_03hs20/data/conda_envs/machineLearning/lib/python3.7/http/client.py", line 1323, in _send_request
    self.endheaders(body, encode_chunked=encode_chunked)
  File "/usr/itetnas04/data-scratch-01/dlim_03hs20/data/conda_envs/machineLearning/lib/python3.7/http/client.py", line 1272, in endheaders
    self._send_output(message_body, encode_chunked=encode_chunked)
  File "/usr/itetnas04/data-scratch-01/dlim_03hs20/data/conda_envs/machineLearning/lib/python3.7/http/client.py", line 1032, in _send_output
    self.send(msg)
  File "/usr/itetnas04/data-scratch-01/dlim_03hs20/data/conda_envs/machineLearning/lib/python3.7/http/client.py", line 972, in send
    self.connect()
  File "/usr/itetnas04/data-scratch-01/dlim_03hs20/data/conda_envs/machineLearning/lib/python3.7/site-packages/urllib3/connection.py", line 187, in connect
    conn = self._new_conn()
  File "/usr/itetnas04/data-scratch-01/dlim_03hs20/data/conda_envs/machineLearning/lib/python3.7/site-packages/urllib3/connection.py", line 172, in _new_conn
    self, "Failed to establish a new connection: %s" % e
urllib3.exceptions.NewConnectionError: <urllib3.connection.HTTPConnection object at 0x7fcd7b5d67d0>: Failed to establish a new connection: [Errno 111] Connection refused

During handling of the above exception, another exception occurred:

Traceback (most recent call last):
  File "/usr/itetnas04/data-scratch-01/dlim_03hs20/data/conda_envs/machineLearning/lib/python3.7/site-packages/requests/adapters.py", line 449, in send
    timeout=timeout
  File "/usr/itetnas04/data-scratch-01/dlim_03hs20/data/conda_envs/machineLearning/lib/python3.7/site-packages/urllib3/connectionpool.py", line 727, in urlopen
    method, url, error=e, _pool=self, _stacktrace=sys.exc_info()[2]
  File "/usr/itetnas04/data-scratch-01/dlim_03hs20/data/conda_envs/machineLearning/lib/python3.7/site-packages/urllib3/util/retry.py", line 439, in increment
    raise MaxRetryError(_pool, url, error or ResponseError(cause))
urllib3.exceptions.MaxRetryError: HTTPConnectionPool(host='localhost', port=8097): Max retries exceeded with url: /events (Caused by NewConnectionError('<urllib3.connection.HTTPConnection object at 0x7fcd7b5d67d0>: Failed to establish a new connection: [Errno 111] Connection refused'))

During handling of the above exception, another exception occurred:

Traceback (most recent call last):
  File "/usr/itetnas04/data-scratch-01/dlim_03hs20/data/conda_envs/machineLearning/lib/python3.7/site-packages/visdom/__init__.py", line 711, in _send
    data=json.dumps(msg),
  File "/usr/itetnas04/data-scratch-01/dlim_03hs20/data/conda_envs/machineLearning/lib/python3.7/site-packages/visdom/__init__.py", line 677, in _handle_post
    r = self.session.post(url, data=data)
  File "/usr/itetnas04/data-scratch-01/dlim_03hs20/data/conda_envs/machineLearning/lib/python3.7/site-packages/requests/sessions.py", line 578, in post
    return self.request('POST', url, data=data, json=json, **kwargs)
  File "/usr/itetnas04/data-scratch-01/dlim_03hs20/data/conda_envs/machineLearning/lib/python3.7/site-packages/requests/sessions.py", line 530, in request
    resp = self.send(prep, **send_kwargs)
  File "/usr/itetnas04/data-scratch-01/dlim_03hs20/data/conda_envs/machineLearning/lib/python3.7/site-packages/requests/sessions.py", line 643, in send
    r = adapter.send(request, **kwargs)
  File "/usr/itetnas04/data-scratch-01/dlim_03hs20/data/conda_envs/machineLearning/lib/python3.7/site-packages/requests/adapters.py", line 516, in send
    raise ConnectionError(e, request=request)
requests.exceptions.ConnectionError: HTTPConnectionPool(host='localhost', port=8097): Max retries exceeded with url: /events (Caused by NewConnectionError('<urllib3.connection.HTTPConnection object at 0x7fcd7b5d67d0>: Failed to establish a new connection: [Errno 111] Connection refused'))
Traceback (most recent call last):
  File "/usr/itetnas04/data-scratch-01/dlim_03hs20/data/conda_envs/machineLearning/lib/python3.7/site-packages/urllib3/connection.py", line 160, in _new_conn
    (self._dns_host, self.port), self.timeout, **extra_kw
  File "/usr/itetnas04/data-scratch-01/dlim_03hs20/data/conda_envs/machineLearning/lib/python3.7/site-packages/urllib3/util/connection.py", line 84, in create_connection
    raise err
  File "/usr/itetnas04/data-scratch-01/dlim_03hs20/data/conda_envs/machineLearning/lib/python3.7/site-packages/urllib3/util/connection.py", line 74, in create_connection
    sock.connect(sa)
ConnectionRefusedError: [Errno 111] Connection refused

During handling of the above exception, another exception occurred:

Traceback (most recent call last):
  File "/usr/itetnas04/data-scratch-01/dlim_03hs20/data/conda_envs/machineLearning/lib/python3.7/site-packages/urllib3/connectionpool.py", line 677, in urlopen
    chunked=chunked,
  File "/usr/itetnas04/data-scratch-01/dlim_03hs20/data/conda_envs/machineLearning/lib/python3.7/site-packages/urllib3/connectionpool.py", line 392, in _make_request
    conn.request(method, url, **httplib_request_kw)
  File "/usr/itetnas04/data-scratch-01/dlim_03hs20/data/conda_envs/machineLearning/lib/python3.7/http/client.py", line 1277, in request
    self._send_request(method, url, body, headers, encode_chunked)
  File "/usr/itetnas04/data-scratch-01/dlim_03hs20/data/conda_envs/machineLearning/lib/python3.7/http/client.py", line 1323, in _send_request
    self.endheaders(body, encode_chunked=encode_chunked)
  File "/usr/itetnas04/data-scratch-01/dlim_03hs20/data/conda_envs/machineLearning/lib/python3.7/http/client.py", line 1272, in endheaders
    self._send_output(message_body, encode_chunked=encode_chunked)
  File "/usr/itetnas04/data-scratch-01/dlim_03hs20/data/conda_envs/machineLearning/lib/python3.7/http/client.py", line 1032, in _send_output
    self.send(msg)
  File "/usr/itetnas04/data-scratch-01/dlim_03hs20/data/conda_envs/machineLearning/lib/python3.7/http/client.py", line 972, in send
    self.connect()
  File "/usr/itetnas04/data-scratch-01/dlim_03hs20/data/conda_envs/machineLearning/lib/python3.7/site-packages/urllib3/connection.py", line 187, in connect
    conn = self._new_conn()
  File "/usr/itetnas04/data-scratch-01/dlim_03hs20/data/conda_envs/machineLearning/lib/python3.7/site-packages/urllib3/connection.py", line 172, in _new_conn
    self, "Failed to establish a new connection: %s" % e
urllib3.exceptions.NewConnectionError: <urllib3.connection.HTTPConnection object at 0x7fcd7a407090>: Failed to establish a new connection: [Errno 111] Connection refused

During handling of the above exception, another exception occurred:

Traceback (most recent call last):
  File "/usr/itetnas04/data-scratch-01/dlim_03hs20/data/conda_envs/machineLearning/lib/python3.7/site-packages/requests/adapters.py", line 449, in send
    timeout=timeout
  File "/usr/itetnas04/data-scratch-01/dlim_03hs20/data/conda_envs/machineLearning/lib/python3.7/site-packages/urllib3/connectionpool.py", line 727, in urlopen
    method, url, error=e, _pool=self, _stacktrace=sys.exc_info()[2]
  File "/usr/itetnas04/data-scratch-01/dlim_03hs20/data/conda_envs/machineLearning/lib/python3.7/site-packages/urllib3/util/retry.py", line 439, in increment
    raise MaxRetryError(_pool, url, error or ResponseError(cause))
urllib3.exceptions.MaxRetryError: HTTPConnectionPool(host='localhost', port=8097): Max retries exceeded with url: /events (Caused by NewConnectionError('<urllib3.connection.HTTPConnection object at 0x7fcd7a407090>: Failed to establish a new connection: [Errno 111] Connection refused'))

During handling of the above exception, another exception occurred:

Traceback (most recent call last):
  File "/usr/itetnas04/data-scratch-01/dlim_03hs20/data/conda_envs/machineLearning/lib/python3.7/site-packages/visdom/__init__.py", line 711, in _send
    data=json.dumps(msg),
  File "/usr/itetnas04/data-scratch-01/dlim_03hs20/data/conda_envs/machineLearning/lib/python3.7/site-packages/visdom/__init__.py", line 677, in _handle_post
    r = self.session.post(url, data=data)
  File "/usr/itetnas04/data-scratch-01/dlim_03hs20/data/conda_envs/machineLearning/lib/python3.7/site-packages/requests/sessions.py", line 578, in post
    return self.request('POST', url, data=data, json=json, **kwargs)
  File "/usr/itetnas04/data-scratch-01/dlim_03hs20/data/conda_envs/machineLearning/lib/python3.7/site-packages/requests/sessions.py", line 530, in request
    resp = self.send(prep, **send_kwargs)
  File "/usr/itetnas04/data-scratch-01/dlim_03hs20/data/conda_envs/machineLearning/lib/python3.7/site-packages/requests/sessions.py", line 643, in send
    r = adapter.send(request, **kwargs)
  File "/usr/itetnas04/data-scratch-01/dlim_03hs20/data/conda_envs/machineLearning/lib/python3.7/site-packages/requests/adapters.py", line 516, in send
    raise ConnectionError(e, request=request)
requests.exceptions.ConnectionError: HTTPConnectionPool(host='localhost', port=8097): Max retries exceeded with url: /events (Caused by NewConnectionError('<urllib3.connection.HTTPConnection object at 0x7fcd7a407090>: Failed to establish a new connection: [Errno 111] Connection refused'))
Traceback (most recent call last):
  File "/usr/itetnas04/data-scratch-01/dlim_03hs20/data/conda_envs/machineLearning/lib/python3.7/site-packages/urllib3/connection.py", line 160, in _new_conn
    (self._dns_host, self.port), self.timeout, **extra_kw
  File "/usr/itetnas04/data-scratch-01/dlim_03hs20/data/conda_envs/machineLearning/lib/python3.7/site-packages/urllib3/util/connection.py", line 84, in create_connection
    raise err
  File "/usr/itetnas04/data-scratch-01/dlim_03hs20/data/conda_envs/machineLearning/lib/python3.7/site-packages/urllib3/util/connection.py", line 74, in create_connection
    sock.connect(sa)
ConnectionRefusedError: [Errno 111] Connection refused

During handling of the above exception, another exception occurred:

Traceback (most recent call last):
  File "/usr/itetnas04/data-scratch-01/dlim_03hs20/data/conda_envs/machineLearning/lib/python3.7/site-packages/urllib3/connectionpool.py", line 677, in urlopen
    chunked=chunked,
  File "/usr/itetnas04/data-scratch-01/dlim_03hs20/data/conda_envs/machineLearning/lib/python3.7/site-packages/urllib3/connectionpool.py", line 392, in _make_request
    conn.request(method, url, **httplib_request_kw)
  File "/usr/itetnas04/data-scratch-01/dlim_03hs20/data/conda_envs/machineLearning/lib/python3.7/http/client.py", line 1277, in request
    self._send_request(method, url, body, headers, encode_chunked)
  File "/usr/itetnas04/data-scratch-01/dlim_03hs20/data/conda_envs/machineLearning/lib/python3.7/http/client.py", line 1323, in _send_request
    self.endheaders(body, encode_chunked=encode_chunked)
  File "/usr/itetnas04/data-scratch-01/dlim_03hs20/data/conda_envs/machineLearning/lib/python3.7/http/client.py", line 1272, in endheaders
    self._send_output(message_body, encode_chunked=encode_chunked)
  File "/usr/itetnas04/data-scratch-01/dlim_03hs20/data/conda_envs/machineLearning/lib/python3.7/http/client.py", line 1032, in _send_output
    self.send(msg)
  File "/usr/itetnas04/data-scratch-01/dlim_03hs20/data/conda_envs/machineLearning/lib/python3.7/http/client.py", line 972, in send
    self.connect()
  File "/usr/itetnas04/data-scratch-01/dlim_03hs20/data/conda_envs/machineLearning/lib/python3.7/site-packages/urllib3/connection.py", line 187, in connect
    conn = self._new_conn()
  File "/usr/itetnas04/data-scratch-01/dlim_03hs20/data/conda_envs/machineLearning/lib/python3.7/site-packages/urllib3/connection.py", line 172, in _new_conn
    self, "Failed to establish a new connection: %s" % e
urllib3.exceptions.NewConnectionError: <urllib3.connection.HTTPConnection object at 0x7fcd7a403d10>: Failed to establish a new connection: [Errno 111] Connection refused

During handling of the above exception, another exception occurred:

Traceback (most recent call last):
  File "/usr/itetnas04/data-scratch-01/dlim_03hs20/data/conda_envs/machineLearning/lib/python3.7/site-packages/requests/adapters.py", line 449, in send
    timeout=timeout
  File "/usr/itetnas04/data-scratch-01/dlim_03hs20/data/conda_envs/machineLearning/lib/python3.7/site-packages/urllib3/connectionpool.py", line 727, in urlopen
    method, url, error=e, _pool=self, _stacktrace=sys.exc_info()[2]
  File "/usr/itetnas04/data-scratch-01/dlim_03hs20/data/conda_envs/machineLearning/lib/python3.7/site-packages/urllib3/util/retry.py", line 439, in increment
    raise MaxRetryError(_pool, url, error or ResponseError(cause))
urllib3.exceptions.MaxRetryError: HTTPConnectionPool(host='localhost', port=8097): Max retries exceeded with url: /events (Caused by NewConnectionError('<urllib3.connection.HTTPConnection object at 0x7fcd7a403d10>: Failed to establish a new connection: [Errno 111] Connection refused'))

During handling of the above exception, another exception occurred:

Traceback (most recent call last):
  File "/usr/itetnas04/data-scratch-01/dlim_03hs20/data/conda_envs/machineLearning/lib/python3.7/site-packages/visdom/__init__.py", line 711, in _send
    data=json.dumps(msg),
  File "/usr/itetnas04/data-scratch-01/dlim_03hs20/data/conda_envs/machineLearning/lib/python3.7/site-packages/visdom/__init__.py", line 677, in _handle_post
    r = self.session.post(url, data=data)
  File "/usr/itetnas04/data-scratch-01/dlim_03hs20/data/conda_envs/machineLearning/lib/python3.7/site-packages/requests/sessions.py", line 578, in post
    return self.request('POST', url, data=data, json=json, **kwargs)
  File "/usr/itetnas04/data-scratch-01/dlim_03hs20/data/conda_envs/machineLearning/lib/python3.7/site-packages/requests/sessions.py", line 530, in request
    resp = self.send(prep, **send_kwargs)
  File "/usr/itetnas04/data-scratch-01/dlim_03hs20/data/conda_envs/machineLearning/lib/python3.7/site-packages/requests/sessions.py", line 643, in send
    r = adapter.send(request, **kwargs)
  File "/usr/itetnas04/data-scratch-01/dlim_03hs20/data/conda_envs/machineLearning/lib/python3.7/site-packages/requests/adapters.py", line 516, in send
    raise ConnectionError(e, request=request)
requests.exceptions.ConnectionError: HTTPConnectionPool(host='localhost', port=8097): Max retries exceeded with url: /events (Caused by NewConnectionError('<urllib3.connection.HTTPConnection object at 0x7fcd7a403d10>: Failed to establish a new connection: [Errno 111] Connection refused'))
Traceback (most recent call last):
  File "/usr/itetnas04/data-scratch-01/dlim_03hs20/data/conda_envs/machineLearning/lib/python3.7/site-packages/urllib3/connection.py", line 160, in _new_conn
    (self._dns_host, self.port), self.timeout, **extra_kw
  File "/usr/itetnas04/data-scratch-01/dlim_03hs20/data/conda_envs/machineLearning/lib/python3.7/site-packages/urllib3/util/connection.py", line 84, in create_connection
    raise err
  File "/usr/itetnas04/data-scratch-01/dlim_03hs20/data/conda_envs/machineLearning/lib/python3.7/site-packages/urllib3/util/connection.py", line 74, in create_connection
    sock.connect(sa)
ConnectionRefusedError: [Errno 111] Connection refused

During handling of the above exception, another exception occurred:

Traceback (most recent call last):
  File "/usr/itetnas04/data-scratch-01/dlim_03hs20/data/conda_envs/machineLearning/lib/python3.7/site-packages/urllib3/connectionpool.py", line 677, in urlopen
    chunked=chunked,
  File "/usr/itetnas04/data-scratch-01/dlim_03hs20/data/conda_envs/machineLearning/lib/python3.7/site-packages/urllib3/connectionpool.py", line 392, in _make_request
    conn.request(method, url, **httplib_request_kw)
  File "/usr/itetnas04/data-scratch-01/dlim_03hs20/data/conda_envs/machineLearning/lib/python3.7/http/client.py", line 1277, in request
    self._send_request(method, url, body, headers, encode_chunked)
  File "/usr/itetnas04/data-scratch-01/dlim_03hs20/data/conda_envs/machineLearning/lib/python3.7/http/client.py", line 1323, in _send_request
    self.endheaders(body, encode_chunked=encode_chunked)
  File "/usr/itetnas04/data-scratch-01/dlim_03hs20/data/conda_envs/machineLearning/lib/python3.7/http/client.py", line 1272, in endheaders
    self._send_output(message_body, encode_chunked=encode_chunked)
  File "/usr/itetnas04/data-scratch-01/dlim_03hs20/data/conda_envs/machineLearning/lib/python3.7/http/client.py", line 1032, in _send_output
    self.send(msg)
  File "/usr/itetnas04/data-scratch-01/dlim_03hs20/data/conda_envs/machineLearning/lib/python3.7/http/client.py", line 972, in send
    self.connect()
  File "/usr/itetnas04/data-scratch-01/dlim_03hs20/data/conda_envs/machineLearning/lib/python3.7/site-packages/urllib3/connection.py", line 187, in connect
    conn = self._new_conn()
  File "/usr/itetnas04/data-scratch-01/dlim_03hs20/data/conda_envs/machineLearning/lib/python3.7/site-packages/urllib3/connection.py", line 172, in _new_conn
    self, "Failed to establish a new connection: %s" % e
urllib3.exceptions.NewConnectionError: <urllib3.connection.HTTPConnection object at 0x7fcd7b5d65d0>: Failed to establish a new connection: [Errno 111] Connection refused

During handling of the above exception, another exception occurred:

Traceback (most recent call last):
  File "/usr/itetnas04/data-scratch-01/dlim_03hs20/data/conda_envs/machineLearning/lib/python3.7/site-packages/requests/adapters.py", line 449, in send
    timeout=timeout
  File "/usr/itetnas04/data-scratch-01/dlim_03hs20/data/conda_envs/machineLearning/lib/python3.7/site-packages/urllib3/connectionpool.py", line 727, in urlopen
    method, url, error=e, _pool=self, _stacktrace=sys.exc_info()[2]
  File "/usr/itetnas04/data-scratch-01/dlim_03hs20/data/conda_envs/machineLearning/lib/python3.7/site-packages/urllib3/util/retry.py", line 439, in increment
    raise MaxRetryError(_pool, url, error or ResponseError(cause))
urllib3.exceptions.MaxRetryError: HTTPConnectionPool(host='localhost', port=8097): Max retries exceeded with url: /events (Caused by NewConnectionError('<urllib3.connection.HTTPConnection object at 0x7fcd7b5d65d0>: Failed to establish a new connection: [Errno 111] Connection refused'))

During handling of the above exception, another exception occurred:

Traceback (most recent call last):
  File "/usr/itetnas04/data-scratch-01/dlim_03hs20/data/conda_envs/machineLearning/lib/python3.7/site-packages/visdom/__init__.py", line 711, in _send
    data=json.dumps(msg),
  File "/usr/itetnas04/data-scratch-01/dlim_03hs20/data/conda_envs/machineLearning/lib/python3.7/site-packages/visdom/__init__.py", line 677, in _handle_post
    r = self.session.post(url, data=data)
  File "/usr/itetnas04/data-scratch-01/dlim_03hs20/data/conda_envs/machineLearning/lib/python3.7/site-packages/requests/sessions.py", line 578, in post
    return self.request('POST', url, data=data, json=json, **kwargs)
  File "/usr/itetnas04/data-scratch-01/dlim_03hs20/data/conda_envs/machineLearning/lib/python3.7/site-packages/requests/sessions.py", line 530, in request
    resp = self.send(prep, **send_kwargs)
  File "/usr/itetnas04/data-scratch-01/dlim_03hs20/data/conda_envs/machineLearning/lib/python3.7/site-packages/requests/sessions.py", line 643, in send
    r = adapter.send(request, **kwargs)
  File "/usr/itetnas04/data-scratch-01/dlim_03hs20/data/conda_envs/machineLearning/lib/python3.7/site-packages/requests/adapters.py", line 516, in send
    raise ConnectionError(e, request=request)
requests.exceptions.ConnectionError: HTTPConnectionPool(host='localhost', port=8097): Max retries exceeded with url: /events (Caused by NewConnectionError('<urllib3.connection.HTTPConnection object at 0x7fcd7b5d65d0>: Failed to establish a new connection: [Errno 111] Connection refused'))
Traceback (most recent call last):
  File "/usr/itetnas04/data-scratch-01/dlim_03hs20/data/conda_envs/machineLearning/lib/python3.7/site-packages/urllib3/connection.py", line 160, in _new_conn
    (self._dns_host, self.port), self.timeout, **extra_kw
  File "/usr/itetnas04/data-scratch-01/dlim_03hs20/data/conda_envs/machineLearning/lib/python3.7/site-packages/urllib3/util/connection.py", line 84, in create_connection
    raise err
  File "/usr/itetnas04/data-scratch-01/dlim_03hs20/data/conda_envs/machineLearning/lib/python3.7/site-packages/urllib3/util/connection.py", line 74, in create_connection
    sock.connect(sa)
ConnectionRefusedError: [Errno 111] Connection refused

During handling of the above exception, another exception occurred:

Traceback (most recent call last):
  File "/usr/itetnas04/data-scratch-01/dlim_03hs20/data/conda_envs/machineLearning/lib/python3.7/site-packages/urllib3/connectionpool.py", line 677, in urlopen
    chunked=chunked,
  File "/usr/itetnas04/data-scratch-01/dlim_03hs20/data/conda_envs/machineLearning/lib/python3.7/site-packages/urllib3/connectionpool.py", line 392, in _make_request
    conn.request(method, url, **httplib_request_kw)
  File "/usr/itetnas04/data-scratch-01/dlim_03hs20/data/conda_envs/machineLearning/lib/python3.7/http/client.py", line 1277, in request
    self._send_request(method, url, body, headers, encode_chunked)
  File "/usr/itetnas04/data-scratch-01/dlim_03hs20/data/conda_envs/machineLearning/lib/python3.7/http/client.py", line 1323, in _send_request
    self.endheaders(body, encode_chunked=encode_chunked)
  File "/usr/itetnas04/data-scratch-01/dlim_03hs20/data/conda_envs/machineLearning/lib/python3.7/http/client.py", line 1272, in endheaders
    self._send_output(message_body, encode_chunked=encode_chunked)
  File "/usr/itetnas04/data-scratch-01/dlim_03hs20/data/conda_envs/machineLearning/lib/python3.7/http/client.py", line 1032, in _send_output
    self.send(msg)
  File "/usr/itetnas04/data-scratch-01/dlim_03hs20/data/conda_envs/machineLearning/lib/python3.7/http/client.py", line 972, in send
    self.connect()
  File "/usr/itetnas04/data-scratch-01/dlim_03hs20/data/conda_envs/machineLearning/lib/python3.7/site-packages/urllib3/connection.py", line 187, in connect
    conn = self._new_conn()
  File "/usr/itetnas04/data-scratch-01/dlim_03hs20/data/conda_envs/machineLearning/lib/python3.7/site-packages/urllib3/connection.py", line 172, in _new_conn
    self, "Failed to establish a new connection: %s" % e
urllib3.exceptions.NewConnectionError: <urllib3.connection.HTTPConnection object at 0x7fcd7b5d6390>: Failed to establish a new connection: [Errno 111] Connection refused

During handling of the above exception, another exception occurred:

Traceback (most recent call last):
  File "/usr/itetnas04/data-scratch-01/dlim_03hs20/data/conda_envs/machineLearning/lib/python3.7/site-packages/requests/adapters.py", line 449, in send
    timeout=timeout
  File "/usr/itetnas04/data-scratch-01/dlim_03hs20/data/conda_envs/machineLearning/lib/python3.7/site-packages/urllib3/connectionpool.py", line 727, in urlopen
    method, url, error=e, _pool=self, _stacktrace=sys.exc_info()[2]
  File "/usr/itetnas04/data-scratch-01/dlim_03hs20/data/conda_envs/machineLearning/lib/python3.7/site-packages/urllib3/util/retry.py", line 439, in increment
    raise MaxRetryError(_pool, url, error or ResponseError(cause))
urllib3.exceptions.MaxRetryError: HTTPConnectionPool(host='localhost', port=8097): Max retries exceeded with url: /events (Caused by NewConnectionError('<urllib3.connection.HTTPConnection object at 0x7fcd7b5d6390>: Failed to establish a new connection: [Errno 111] Connection refused'))

During handling of the above exception, another exception occurred:

Traceback (most recent call last):
  File "/usr/itetnas04/data-scratch-01/dlim_03hs20/data/conda_envs/machineLearning/lib/python3.7/site-packages/visdom/__init__.py", line 711, in _send
    data=json.dumps(msg),
  File "/usr/itetnas04/data-scratch-01/dlim_03hs20/data/conda_envs/machineLearning/lib/python3.7/site-packages/visdom/__init__.py", line 677, in _handle_post
    r = self.session.post(url, data=data)
  File "/usr/itetnas04/data-scratch-01/dlim_03hs20/data/conda_envs/machineLearning/lib/python3.7/site-packages/requests/sessions.py", line 578, in post
    return self.request('POST', url, data=data, json=json, **kwargs)
  File "/usr/itetnas04/data-scratch-01/dlim_03hs20/data/conda_envs/machineLearning/lib/python3.7/site-packages/requests/sessions.py", line 530, in request
    resp = self.send(prep, **send_kwargs)
  File "/usr/itetnas04/data-scratch-01/dlim_03hs20/data/conda_envs/machineLearning/lib/python3.7/site-packages/requests/sessions.py", line 643, in send
    r = adapter.send(request, **kwargs)
  File "/usr/itetnas04/data-scratch-01/dlim_03hs20/data/conda_envs/machineLearning/lib/python3.7/site-packages/requests/adapters.py", line 516, in send
    raise ConnectionError(e, request=request)
requests.exceptions.ConnectionError: HTTPConnectionPool(host='localhost', port=8097): Max retries exceeded with url: /events (Caused by NewConnectionError('<urllib3.connection.HTTPConnection object at 0x7fcd7b5d6390>: Failed to establish a new connection: [Errno 111] Connection refused'))
(epoch: 4, iters: 100, time: 0.058, data: 0.198) G_GAN: 3.354 G_L1: 38.753 D_real: 0.125 D_fake: 0.058 
Exception in user code:
------------------------------------------------------------
(epoch: 4, iters: 200, time: 0.060, data: 0.002) G_GAN: 2.002 G_L1: 44.083 D_real: 0.066 D_fake: 0.329 
Exception in user code:
------------------------------------------------------------
(epoch: 4, iters: 300, time: 0.058, data: 0.001) G_GAN: 4.593 G_L1: 36.449 D_real: 0.068 D_fake: 0.019 
Exception in user code:
------------------------------------------------------------
Exception in user code:
------------------------------------------------------------
Exception in user code:
------------------------------------------------------------
(epoch: 4, iters: 400, time: 0.255, data: 0.002) G_GAN: 4.001 G_L1: 30.818 D_real: 0.453 D_fake: 0.010 
Exception in user code:
------------------------------------------------------------
End of epoch 4 / 200 	 Time Taken: 20 sec
learning rate 0.0002000 -> 0.0002000
Traceback (most recent call last):
  File "/usr/itetnas04/data-scratch-01/dlim_03hs20/data/conda_envs/machineLearning/lib/python3.7/site-packages/urllib3/connection.py", line 160, in _new_conn
    (self._dns_host, self.port), self.timeout, **extra_kw
  File "/usr/itetnas04/data-scratch-01/dlim_03hs20/data/conda_envs/machineLearning/lib/python3.7/site-packages/urllib3/util/connection.py", line 84, in create_connection
    raise err
  File "/usr/itetnas04/data-scratch-01/dlim_03hs20/data/conda_envs/machineLearning/lib/python3.7/site-packages/urllib3/util/connection.py", line 74, in create_connection
    sock.connect(sa)
ConnectionRefusedError: [Errno 111] Connection refused

During handling of the above exception, another exception occurred:

Traceback (most recent call last):
  File "/usr/itetnas04/data-scratch-01/dlim_03hs20/data/conda_envs/machineLearning/lib/python3.7/site-packages/urllib3/connectionpool.py", line 677, in urlopen
    chunked=chunked,
  File "/usr/itetnas04/data-scratch-01/dlim_03hs20/data/conda_envs/machineLearning/lib/python3.7/site-packages/urllib3/connectionpool.py", line 392, in _make_request
    conn.request(method, url, **httplib_request_kw)
  File "/usr/itetnas04/data-scratch-01/dlim_03hs20/data/conda_envs/machineLearning/lib/python3.7/http/client.py", line 1277, in request
    self._send_request(method, url, body, headers, encode_chunked)
  File "/usr/itetnas04/data-scratch-01/dlim_03hs20/data/conda_envs/machineLearning/lib/python3.7/http/client.py", line 1323, in _send_request
    self.endheaders(body, encode_chunked=encode_chunked)
  File "/usr/itetnas04/data-scratch-01/dlim_03hs20/data/conda_envs/machineLearning/lib/python3.7/http/client.py", line 1272, in endheaders
    self._send_output(message_body, encode_chunked=encode_chunked)
  File "/usr/itetnas04/data-scratch-01/dlim_03hs20/data/conda_envs/machineLearning/lib/python3.7/http/client.py", line 1032, in _send_output
    self.send(msg)
  File "/usr/itetnas04/data-scratch-01/dlim_03hs20/data/conda_envs/machineLearning/lib/python3.7/http/client.py", line 972, in send
    self.connect()
  File "/usr/itetnas04/data-scratch-01/dlim_03hs20/data/conda_envs/machineLearning/lib/python3.7/site-packages/urllib3/connection.py", line 187, in connect
    conn = self._new_conn()
  File "/usr/itetnas04/data-scratch-01/dlim_03hs20/data/conda_envs/machineLearning/lib/python3.7/site-packages/urllib3/connection.py", line 172, in _new_conn
    self, "Failed to establish a new connection: %s" % e
urllib3.exceptions.NewConnectionError: <urllib3.connection.HTTPConnection object at 0x7fcd7a407050>: Failed to establish a new connection: [Errno 111] Connection refused

During handling of the above exception, another exception occurred:

Traceback (most recent call last):
  File "/usr/itetnas04/data-scratch-01/dlim_03hs20/data/conda_envs/machineLearning/lib/python3.7/site-packages/requests/adapters.py", line 449, in send
    timeout=timeout
  File "/usr/itetnas04/data-scratch-01/dlim_03hs20/data/conda_envs/machineLearning/lib/python3.7/site-packages/urllib3/connectionpool.py", line 727, in urlopen
    method, url, error=e, _pool=self, _stacktrace=sys.exc_info()[2]
  File "/usr/itetnas04/data-scratch-01/dlim_03hs20/data/conda_envs/machineLearning/lib/python3.7/site-packages/urllib3/util/retry.py", line 439, in increment
    raise MaxRetryError(_pool, url, error or ResponseError(cause))
urllib3.exceptions.MaxRetryError: HTTPConnectionPool(host='localhost', port=8097): Max retries exceeded with url: /events (Caused by NewConnectionError('<urllib3.connection.HTTPConnection object at 0x7fcd7a407050>: Failed to establish a new connection: [Errno 111] Connection refused'))

During handling of the above exception, another exception occurred:

Traceback (most recent call last):
  File "/usr/itetnas04/data-scratch-01/dlim_03hs20/data/conda_envs/machineLearning/lib/python3.7/site-packages/visdom/__init__.py", line 711, in _send
    data=json.dumps(msg),
  File "/usr/itetnas04/data-scratch-01/dlim_03hs20/data/conda_envs/machineLearning/lib/python3.7/site-packages/visdom/__init__.py", line 677, in _handle_post
    r = self.session.post(url, data=data)
  File "/usr/itetnas04/data-scratch-01/dlim_03hs20/data/conda_envs/machineLearning/lib/python3.7/site-packages/requests/sessions.py", line 578, in post
    return self.request('POST', url, data=data, json=json, **kwargs)
  File "/usr/itetnas04/data-scratch-01/dlim_03hs20/data/conda_envs/machineLearning/lib/python3.7/site-packages/requests/sessions.py", line 530, in request
    resp = self.send(prep, **send_kwargs)
  File "/usr/itetnas04/data-scratch-01/dlim_03hs20/data/conda_envs/machineLearning/lib/python3.7/site-packages/requests/sessions.py", line 643, in send
    r = adapter.send(request, **kwargs)
  File "/usr/itetnas04/data-scratch-01/dlim_03hs20/data/conda_envs/machineLearning/lib/python3.7/site-packages/requests/adapters.py", line 516, in send
    raise ConnectionError(e, request=request)
requests.exceptions.ConnectionError: HTTPConnectionPool(host='localhost', port=8097): Max retries exceeded with url: /events (Caused by NewConnectionError('<urllib3.connection.HTTPConnection object at 0x7fcd7a407050>: Failed to establish a new connection: [Errno 111] Connection refused'))
Traceback (most recent call last):
  File "/usr/itetnas04/data-scratch-01/dlim_03hs20/data/conda_envs/machineLearning/lib/python3.7/site-packages/urllib3/connection.py", line 160, in _new_conn
    (self._dns_host, self.port), self.timeout, **extra_kw
  File "/usr/itetnas04/data-scratch-01/dlim_03hs20/data/conda_envs/machineLearning/lib/python3.7/site-packages/urllib3/util/connection.py", line 84, in create_connection
    raise err
  File "/usr/itetnas04/data-scratch-01/dlim_03hs20/data/conda_envs/machineLearning/lib/python3.7/site-packages/urllib3/util/connection.py", line 74, in create_connection
    sock.connect(sa)
ConnectionRefusedError: [Errno 111] Connection refused

During handling of the above exception, another exception occurred:

Traceback (most recent call last):
  File "/usr/itetnas04/data-scratch-01/dlim_03hs20/data/conda_envs/machineLearning/lib/python3.7/site-packages/urllib3/connectionpool.py", line 677, in urlopen
    chunked=chunked,
  File "/usr/itetnas04/data-scratch-01/dlim_03hs20/data/conda_envs/machineLearning/lib/python3.7/site-packages/urllib3/connectionpool.py", line 392, in _make_request
    conn.request(method, url, **httplib_request_kw)
  File "/usr/itetnas04/data-scratch-01/dlim_03hs20/data/conda_envs/machineLearning/lib/python3.7/http/client.py", line 1277, in request
    self._send_request(method, url, body, headers, encode_chunked)
  File "/usr/itetnas04/data-scratch-01/dlim_03hs20/data/conda_envs/machineLearning/lib/python3.7/http/client.py", line 1323, in _send_request
    self.endheaders(body, encode_chunked=encode_chunked)
  File "/usr/itetnas04/data-scratch-01/dlim_03hs20/data/conda_envs/machineLearning/lib/python3.7/http/client.py", line 1272, in endheaders
    self._send_output(message_body, encode_chunked=encode_chunked)
  File "/usr/itetnas04/data-scratch-01/dlim_03hs20/data/conda_envs/machineLearning/lib/python3.7/http/client.py", line 1032, in _send_output
    self.send(msg)
  File "/usr/itetnas04/data-scratch-01/dlim_03hs20/data/conda_envs/machineLearning/lib/python3.7/http/client.py", line 972, in send
    self.connect()
  File "/usr/itetnas04/data-scratch-01/dlim_03hs20/data/conda_envs/machineLearning/lib/python3.7/site-packages/urllib3/connection.py", line 187, in connect
    conn = self._new_conn()
  File "/usr/itetnas04/data-scratch-01/dlim_03hs20/data/conda_envs/machineLearning/lib/python3.7/site-packages/urllib3/connection.py", line 172, in _new_conn
    self, "Failed to establish a new connection: %s" % e
urllib3.exceptions.NewConnectionError: <urllib3.connection.HTTPConnection object at 0x7fcd7a403590>: Failed to establish a new connection: [Errno 111] Connection refused

During handling of the above exception, another exception occurred:

Traceback (most recent call last):
  File "/usr/itetnas04/data-scratch-01/dlim_03hs20/data/conda_envs/machineLearning/lib/python3.7/site-packages/requests/adapters.py", line 449, in send
    timeout=timeout
  File "/usr/itetnas04/data-scratch-01/dlim_03hs20/data/conda_envs/machineLearning/lib/python3.7/site-packages/urllib3/connectionpool.py", line 727, in urlopen
    method, url, error=e, _pool=self, _stacktrace=sys.exc_info()[2]
  File "/usr/itetnas04/data-scratch-01/dlim_03hs20/data/conda_envs/machineLearning/lib/python3.7/site-packages/urllib3/util/retry.py", line 439, in increment
    raise MaxRetryError(_pool, url, error or ResponseError(cause))
urllib3.exceptions.MaxRetryError: HTTPConnectionPool(host='localhost', port=8097): Max retries exceeded with url: /events (Caused by NewConnectionError('<urllib3.connection.HTTPConnection object at 0x7fcd7a403590>: Failed to establish a new connection: [Errno 111] Connection refused'))

During handling of the above exception, another exception occurred:

Traceback (most recent call last):
  File "/usr/itetnas04/data-scratch-01/dlim_03hs20/data/conda_envs/machineLearning/lib/python3.7/site-packages/visdom/__init__.py", line 711, in _send
    data=json.dumps(msg),
  File "/usr/itetnas04/data-scratch-01/dlim_03hs20/data/conda_envs/machineLearning/lib/python3.7/site-packages/visdom/__init__.py", line 677, in _handle_post
    r = self.session.post(url, data=data)
  File "/usr/itetnas04/data-scratch-01/dlim_03hs20/data/conda_envs/machineLearning/lib/python3.7/site-packages/requests/sessions.py", line 578, in post
    return self.request('POST', url, data=data, json=json, **kwargs)
  File "/usr/itetnas04/data-scratch-01/dlim_03hs20/data/conda_envs/machineLearning/lib/python3.7/site-packages/requests/sessions.py", line 530, in request
    resp = self.send(prep, **send_kwargs)
  File "/usr/itetnas04/data-scratch-01/dlim_03hs20/data/conda_envs/machineLearning/lib/python3.7/site-packages/requests/sessions.py", line 643, in send
    r = adapter.send(request, **kwargs)
  File "/usr/itetnas04/data-scratch-01/dlim_03hs20/data/conda_envs/machineLearning/lib/python3.7/site-packages/requests/adapters.py", line 516, in send
    raise ConnectionError(e, request=request)
requests.exceptions.ConnectionError: HTTPConnectionPool(host='localhost', port=8097): Max retries exceeded with url: /events (Caused by NewConnectionError('<urllib3.connection.HTTPConnection object at 0x7fcd7a403590>: Failed to establish a new connection: [Errno 111] Connection refused'))
Traceback (most recent call last):
  File "/usr/itetnas04/data-scratch-01/dlim_03hs20/data/conda_envs/machineLearning/lib/python3.7/site-packages/urllib3/connection.py", line 160, in _new_conn
    (self._dns_host, self.port), self.timeout, **extra_kw
  File "/usr/itetnas04/data-scratch-01/dlim_03hs20/data/conda_envs/machineLearning/lib/python3.7/site-packages/urllib3/util/connection.py", line 84, in create_connection
    raise err
  File "/usr/itetnas04/data-scratch-01/dlim_03hs20/data/conda_envs/machineLearning/lib/python3.7/site-packages/urllib3/util/connection.py", line 74, in create_connection
    sock.connect(sa)
ConnectionRefusedError: [Errno 111] Connection refused

During handling of the above exception, another exception occurred:

Traceback (most recent call last):
  File "/usr/itetnas04/data-scratch-01/dlim_03hs20/data/conda_envs/machineLearning/lib/python3.7/site-packages/urllib3/connectionpool.py", line 677, in urlopen
    chunked=chunked,
  File "/usr/itetnas04/data-scratch-01/dlim_03hs20/data/conda_envs/machineLearning/lib/python3.7/site-packages/urllib3/connectionpool.py", line 392, in _make_request
    conn.request(method, url, **httplib_request_kw)
  File "/usr/itetnas04/data-scratch-01/dlim_03hs20/data/conda_envs/machineLearning/lib/python3.7/http/client.py", line 1277, in request
    self._send_request(method, url, body, headers, encode_chunked)
  File "/usr/itetnas04/data-scratch-01/dlim_03hs20/data/conda_envs/machineLearning/lib/python3.7/http/client.py", line 1323, in _send_request
    self.endheaders(body, encode_chunked=encode_chunked)
  File "/usr/itetnas04/data-scratch-01/dlim_03hs20/data/conda_envs/machineLearning/lib/python3.7/http/client.py", line 1272, in endheaders
    self._send_output(message_body, encode_chunked=encode_chunked)
  File "/usr/itetnas04/data-scratch-01/dlim_03hs20/data/conda_envs/machineLearning/lib/python3.7/http/client.py", line 1032, in _send_output
    self.send(msg)
  File "/usr/itetnas04/data-scratch-01/dlim_03hs20/data/conda_envs/machineLearning/lib/python3.7/http/client.py", line 972, in send
    self.connect()
  File "/usr/itetnas04/data-scratch-01/dlim_03hs20/data/conda_envs/machineLearning/lib/python3.7/site-packages/urllib3/connection.py", line 187, in connect
    conn = self._new_conn()
  File "/usr/itetnas04/data-scratch-01/dlim_03hs20/data/conda_envs/machineLearning/lib/python3.7/site-packages/urllib3/connection.py", line 172, in _new_conn
    self, "Failed to establish a new connection: %s" % e
urllib3.exceptions.NewConnectionError: <urllib3.connection.HTTPConnection object at 0x7fcd7b5e0510>: Failed to establish a new connection: [Errno 111] Connection refused

During handling of the above exception, another exception occurred:

Traceback (most recent call last):
  File "/usr/itetnas04/data-scratch-01/dlim_03hs20/data/conda_envs/machineLearning/lib/python3.7/site-packages/requests/adapters.py", line 449, in send
    timeout=timeout
  File "/usr/itetnas04/data-scratch-01/dlim_03hs20/data/conda_envs/machineLearning/lib/python3.7/site-packages/urllib3/connectionpool.py", line 727, in urlopen
    method, url, error=e, _pool=self, _stacktrace=sys.exc_info()[2]
  File "/usr/itetnas04/data-scratch-01/dlim_03hs20/data/conda_envs/machineLearning/lib/python3.7/site-packages/urllib3/util/retry.py", line 439, in increment
    raise MaxRetryError(_pool, url, error or ResponseError(cause))
urllib3.exceptions.MaxRetryError: HTTPConnectionPool(host='localhost', port=8097): Max retries exceeded with url: /events (Caused by NewConnectionError('<urllib3.connection.HTTPConnection object at 0x7fcd7b5e0510>: Failed to establish a new connection: [Errno 111] Connection refused'))

During handling of the above exception, another exception occurred:

Traceback (most recent call last):
  File "/usr/itetnas04/data-scratch-01/dlim_03hs20/data/conda_envs/machineLearning/lib/python3.7/site-packages/visdom/__init__.py", line 711, in _send
    data=json.dumps(msg),
  File "/usr/itetnas04/data-scratch-01/dlim_03hs20/data/conda_envs/machineLearning/lib/python3.7/site-packages/visdom/__init__.py", line 677, in _handle_post
    r = self.session.post(url, data=data)
  File "/usr/itetnas04/data-scratch-01/dlim_03hs20/data/conda_envs/machineLearning/lib/python3.7/site-packages/requests/sessions.py", line 578, in post
    return self.request('POST', url, data=data, json=json, **kwargs)
  File "/usr/itetnas04/data-scratch-01/dlim_03hs20/data/conda_envs/machineLearning/lib/python3.7/site-packages/requests/sessions.py", line 530, in request
    resp = self.send(prep, **send_kwargs)
  File "/usr/itetnas04/data-scratch-01/dlim_03hs20/data/conda_envs/machineLearning/lib/python3.7/site-packages/requests/sessions.py", line 643, in send
    r = adapter.send(request, **kwargs)
  File "/usr/itetnas04/data-scratch-01/dlim_03hs20/data/conda_envs/machineLearning/lib/python3.7/site-packages/requests/adapters.py", line 516, in send
    raise ConnectionError(e, request=request)
requests.exceptions.ConnectionError: HTTPConnectionPool(host='localhost', port=8097): Max retries exceeded with url: /events (Caused by NewConnectionError('<urllib3.connection.HTTPConnection object at 0x7fcd7b5e0510>: Failed to establish a new connection: [Errno 111] Connection refused'))
Traceback (most recent call last):
  File "/usr/itetnas04/data-scratch-01/dlim_03hs20/data/conda_envs/machineLearning/lib/python3.7/site-packages/urllib3/connection.py", line 160, in _new_conn
    (self._dns_host, self.port), self.timeout, **extra_kw
  File "/usr/itetnas04/data-scratch-01/dlim_03hs20/data/conda_envs/machineLearning/lib/python3.7/site-packages/urllib3/util/connection.py", line 84, in create_connection
    raise err
  File "/usr/itetnas04/data-scratch-01/dlim_03hs20/data/conda_envs/machineLearning/lib/python3.7/site-packages/urllib3/util/connection.py", line 74, in create_connection
    sock.connect(sa)
ConnectionRefusedError: [Errno 111] Connection refused

During handling of the above exception, another exception occurred:

Traceback (most recent call last):
  File "/usr/itetnas04/data-scratch-01/dlim_03hs20/data/conda_envs/machineLearning/lib/python3.7/site-packages/urllib3/connectionpool.py", line 677, in urlopen
    chunked=chunked,
  File "/usr/itetnas04/data-scratch-01/dlim_03hs20/data/conda_envs/machineLearning/lib/python3.7/site-packages/urllib3/connectionpool.py", line 392, in _make_request
    conn.request(method, url, **httplib_request_kw)
  File "/usr/itetnas04/data-scratch-01/dlim_03hs20/data/conda_envs/machineLearning/lib/python3.7/http/client.py", line 1277, in request
    self._send_request(method, url, body, headers, encode_chunked)
  File "/usr/itetnas04/data-scratch-01/dlim_03hs20/data/conda_envs/machineLearning/lib/python3.7/http/client.py", line 1323, in _send_request
    self.endheaders(body, encode_chunked=encode_chunked)
  File "/usr/itetnas04/data-scratch-01/dlim_03hs20/data/conda_envs/machineLearning/lib/python3.7/http/client.py", line 1272, in endheaders
    self._send_output(message_body, encode_chunked=encode_chunked)
  File "/usr/itetnas04/data-scratch-01/dlim_03hs20/data/conda_envs/machineLearning/lib/python3.7/http/client.py", line 1032, in _send_output
    self.send(msg)
  File "/usr/itetnas04/data-scratch-01/dlim_03hs20/data/conda_envs/machineLearning/lib/python3.7/http/client.py", line 972, in send
    self.connect()
  File "/usr/itetnas04/data-scratch-01/dlim_03hs20/data/conda_envs/machineLearning/lib/python3.7/site-packages/urllib3/connection.py", line 187, in connect
    conn = self._new_conn()
  File "/usr/itetnas04/data-scratch-01/dlim_03hs20/data/conda_envs/machineLearning/lib/python3.7/site-packages/urllib3/connection.py", line 172, in _new_conn
    self, "Failed to establish a new connection: %s" % e
urllib3.exceptions.NewConnectionError: <urllib3.connection.HTTPConnection object at 0x7fcd7a403fd0>: Failed to establish a new connection: [Errno 111] Connection refused

During handling of the above exception, another exception occurred:

Traceback (most recent call last):
  File "/usr/itetnas04/data-scratch-01/dlim_03hs20/data/conda_envs/machineLearning/lib/python3.7/site-packages/requests/adapters.py", line 449, in send
    timeout=timeout
  File "/usr/itetnas04/data-scratch-01/dlim_03hs20/data/conda_envs/machineLearning/lib/python3.7/site-packages/urllib3/connectionpool.py", line 727, in urlopen
    method, url, error=e, _pool=self, _stacktrace=sys.exc_info()[2]
  File "/usr/itetnas04/data-scratch-01/dlim_03hs20/data/conda_envs/machineLearning/lib/python3.7/site-packages/urllib3/util/retry.py", line 439, in increment
    raise MaxRetryError(_pool, url, error or ResponseError(cause))
urllib3.exceptions.MaxRetryError: HTTPConnectionPool(host='localhost', port=8097): Max retries exceeded with url: /events (Caused by NewConnectionError('<urllib3.connection.HTTPConnection object at 0x7fcd7a403fd0>: Failed to establish a new connection: [Errno 111] Connection refused'))

During handling of the above exception, another exception occurred:

Traceback (most recent call last):
  File "/usr/itetnas04/data-scratch-01/dlim_03hs20/data/conda_envs/machineLearning/lib/python3.7/site-packages/visdom/__init__.py", line 711, in _send
    data=json.dumps(msg),
  File "/usr/itetnas04/data-scratch-01/dlim_03hs20/data/conda_envs/machineLearning/lib/python3.7/site-packages/visdom/__init__.py", line 677, in _handle_post
    r = self.session.post(url, data=data)
  File "/usr/itetnas04/data-scratch-01/dlim_03hs20/data/conda_envs/machineLearning/lib/python3.7/site-packages/requests/sessions.py", line 578, in post
    return self.request('POST', url, data=data, json=json, **kwargs)
  File "/usr/itetnas04/data-scratch-01/dlim_03hs20/data/conda_envs/machineLearning/lib/python3.7/site-packages/requests/sessions.py", line 530, in request
    resp = self.send(prep, **send_kwargs)
  File "/usr/itetnas04/data-scratch-01/dlim_03hs20/data/conda_envs/machineLearning/lib/python3.7/site-packages/requests/sessions.py", line 643, in send
    r = adapter.send(request, **kwargs)
  File "/usr/itetnas04/data-scratch-01/dlim_03hs20/data/conda_envs/machineLearning/lib/python3.7/site-packages/requests/adapters.py", line 516, in send
    raise ConnectionError(e, request=request)
requests.exceptions.ConnectionError: HTTPConnectionPool(host='localhost', port=8097): Max retries exceeded with url: /events (Caused by NewConnectionError('<urllib3.connection.HTTPConnection object at 0x7fcd7a403fd0>: Failed to establish a new connection: [Errno 111] Connection refused'))
Traceback (most recent call last):
  File "/usr/itetnas04/data-scratch-01/dlim_03hs20/data/conda_envs/machineLearning/lib/python3.7/site-packages/urllib3/connection.py", line 160, in _new_conn
    (self._dns_host, self.port), self.timeout, **extra_kw
  File "/usr/itetnas04/data-scratch-01/dlim_03hs20/data/conda_envs/machineLearning/lib/python3.7/site-packages/urllib3/util/connection.py", line 84, in create_connection
    raise err
  File "/usr/itetnas04/data-scratch-01/dlim_03hs20/data/conda_envs/machineLearning/lib/python3.7/site-packages/urllib3/util/connection.py", line 74, in create_connection
    sock.connect(sa)
ConnectionRefusedError: [Errno 111] Connection refused

During handling of the above exception, another exception occurred:

Traceback (most recent call last):
  File "/usr/itetnas04/data-scratch-01/dlim_03hs20/data/conda_envs/machineLearning/lib/python3.7/site-packages/urllib3/connectionpool.py", line 677, in urlopen
    chunked=chunked,
  File "/usr/itetnas04/data-scratch-01/dlim_03hs20/data/conda_envs/machineLearning/lib/python3.7/site-packages/urllib3/connectionpool.py", line 392, in _make_request
    conn.request(method, url, **httplib_request_kw)
  File "/usr/itetnas04/data-scratch-01/dlim_03hs20/data/conda_envs/machineLearning/lib/python3.7/http/client.py", line 1277, in request
    self._send_request(method, url, body, headers, encode_chunked)
  File "/usr/itetnas04/data-scratch-01/dlim_03hs20/data/conda_envs/machineLearning/lib/python3.7/http/client.py", line 1323, in _send_request
    self.endheaders(body, encode_chunked=encode_chunked)
  File "/usr/itetnas04/data-scratch-01/dlim_03hs20/data/conda_envs/machineLearning/lib/python3.7/http/client.py", line 1272, in endheaders
    self._send_output(message_body, encode_chunked=encode_chunked)
  File "/usr/itetnas04/data-scratch-01/dlim_03hs20/data/conda_envs/machineLearning/lib/python3.7/http/client.py", line 1032, in _send_output
    self.send(msg)
  File "/usr/itetnas04/data-scratch-01/dlim_03hs20/data/conda_envs/machineLearning/lib/python3.7/http/client.py", line 972, in send
    self.connect()
  File "/usr/itetnas04/data-scratch-01/dlim_03hs20/data/conda_envs/machineLearning/lib/python3.7/site-packages/urllib3/connection.py", line 187, in connect
    conn = self._new_conn()
  File "/usr/itetnas04/data-scratch-01/dlim_03hs20/data/conda_envs/machineLearning/lib/python3.7/site-packages/urllib3/connection.py", line 172, in _new_conn
    self, "Failed to establish a new connection: %s" % e
urllib3.exceptions.NewConnectionError: <urllib3.connection.HTTPConnection object at 0x7fcd7a4103d0>: Failed to establish a new connection: [Errno 111] Connection refused

During handling of the above exception, another exception occurred:

Traceback (most recent call last):
  File "/usr/itetnas04/data-scratch-01/dlim_03hs20/data/conda_envs/machineLearning/lib/python3.7/site-packages/requests/adapters.py", line 449, in send
    timeout=timeout
  File "/usr/itetnas04/data-scratch-01/dlim_03hs20/data/conda_envs/machineLearning/lib/python3.7/site-packages/urllib3/connectionpool.py", line 727, in urlopen
    method, url, error=e, _pool=self, _stacktrace=sys.exc_info()[2]
  File "/usr/itetnas04/data-scratch-01/dlim_03hs20/data/conda_envs/machineLearning/lib/python3.7/site-packages/urllib3/util/retry.py", line 439, in increment
    raise MaxRetryError(_pool, url, error or ResponseError(cause))
urllib3.exceptions.MaxRetryError: HTTPConnectionPool(host='localhost', port=8097): Max retries exceeded with url: /events (Caused by NewConnectionError('<urllib3.connection.HTTPConnection object at 0x7fcd7a4103d0>: Failed to establish a new connection: [Errno 111] Connection refused'))

During handling of the above exception, another exception occurred:

Traceback (most recent call last):
  File "/usr/itetnas04/data-scratch-01/dlim_03hs20/data/conda_envs/machineLearning/lib/python3.7/site-packages/visdom/__init__.py", line 711, in _send
    data=json.dumps(msg),
  File "/usr/itetnas04/data-scratch-01/dlim_03hs20/data/conda_envs/machineLearning/lib/python3.7/site-packages/visdom/__init__.py", line 677, in _handle_post
    r = self.session.post(url, data=data)
  File "/usr/itetnas04/data-scratch-01/dlim_03hs20/data/conda_envs/machineLearning/lib/python3.7/site-packages/requests/sessions.py", line 578, in post
    return self.request('POST', url, data=data, json=json, **kwargs)
  File "/usr/itetnas04/data-scratch-01/dlim_03hs20/data/conda_envs/machineLearning/lib/python3.7/site-packages/requests/sessions.py", line 530, in request
    resp = self.send(prep, **send_kwargs)
  File "/usr/itetnas04/data-scratch-01/dlim_03hs20/data/conda_envs/machineLearning/lib/python3.7/site-packages/requests/sessions.py", line 643, in send
    r = adapter.send(request, **kwargs)
  File "/usr/itetnas04/data-scratch-01/dlim_03hs20/data/conda_envs/machineLearning/lib/python3.7/site-packages/requests/adapters.py", line 516, in send
    raise ConnectionError(e, request=request)
requests.exceptions.ConnectionError: HTTPConnectionPool(host='localhost', port=8097): Max retries exceeded with url: /events (Caused by NewConnectionError('<urllib3.connection.HTTPConnection object at 0x7fcd7a4103d0>: Failed to establish a new connection: [Errno 111] Connection refused'))
Traceback (most recent call last):
  File "/usr/itetnas04/data-scratch-01/dlim_03hs20/data/conda_envs/machineLearning/lib/python3.7/site-packages/urllib3/connection.py", line 160, in _new_conn
    (self._dns_host, self.port), self.timeout, **extra_kw
  File "/usr/itetnas04/data-scratch-01/dlim_03hs20/data/conda_envs/machineLearning/lib/python3.7/site-packages/urllib3/util/connection.py", line 84, in create_connection
    raise err
  File "/usr/itetnas04/data-scratch-01/dlim_03hs20/data/conda_envs/machineLearning/lib/python3.7/site-packages/urllib3/util/connection.py", line 74, in create_connection
    sock.connect(sa)
ConnectionRefusedError: [Errno 111] Connection refused

During handling of the above exception, another exception occurred:

Traceback (most recent call last):
  File "/usr/itetnas04/data-scratch-01/dlim_03hs20/data/conda_envs/machineLearning/lib/python3.7/site-packages/urllib3/connectionpool.py", line 677, in urlopen
    chunked=chunked,
  File "/usr/itetnas04/data-scratch-01/dlim_03hs20/data/conda_envs/machineLearning/lib/python3.7/site-packages/urllib3/connectionpool.py", line 392, in _make_request
    conn.request(method, url, **httplib_request_kw)
  File "/usr/itetnas04/data-scratch-01/dlim_03hs20/data/conda_envs/machineLearning/lib/python3.7/http/client.py", line 1277, in request
    self._send_request(method, url, body, headers, encode_chunked)
  File "/usr/itetnas04/data-scratch-01/dlim_03hs20/data/conda_envs/machineLearning/lib/python3.7/http/client.py", line 1323, in _send_request
    self.endheaders(body, encode_chunked=encode_chunked)
  File "/usr/itetnas04/data-scratch-01/dlim_03hs20/data/conda_envs/machineLearning/lib/python3.7/http/client.py", line 1272, in endheaders
    self._send_output(message_body, encode_chunked=encode_chunked)
  File "/usr/itetnas04/data-scratch-01/dlim_03hs20/data/conda_envs/machineLearning/lib/python3.7/http/client.py", line 1032, in _send_output
    self.send(msg)
  File "/usr/itetnas04/data-scratch-01/dlim_03hs20/data/conda_envs/machineLearning/lib/python3.7/http/client.py", line 972, in send
    self.connect()
  File "/usr/itetnas04/data-scratch-01/dlim_03hs20/data/conda_envs/machineLearning/lib/python3.7/site-packages/urllib3/connection.py", line 187, in connect
    conn = self._new_conn()
  File "/usr/itetnas04/data-scratch-01/dlim_03hs20/data/conda_envs/machineLearning/lib/python3.7/site-packages/urllib3/connection.py", line 172, in _new_conn
    self, "Failed to establish a new connection: %s" % e
urllib3.exceptions.NewConnectionError: <urllib3.connection.HTTPConnection object at 0x7fcd7b5edc10>: Failed to establish a new connection: [Errno 111] Connection refused

During handling of the above exception, another exception occurred:

Traceback (most recent call last):
  File "/usr/itetnas04/data-scratch-01/dlim_03hs20/data/conda_envs/machineLearning/lib/python3.7/site-packages/requests/adapters.py", line 449, in send
    timeout=timeout
  File "/usr/itetnas04/data-scratch-01/dlim_03hs20/data/conda_envs/machineLearning/lib/python3.7/site-packages/urllib3/connectionpool.py", line 727, in urlopen
    method, url, error=e, _pool=self, _stacktrace=sys.exc_info()[2]
  File "/usr/itetnas04/data-scratch-01/dlim_03hs20/data/conda_envs/machineLearning/lib/python3.7/site-packages/urllib3/util/retry.py", line 439, in increment
    raise MaxRetryError(_pool, url, error or ResponseError(cause))
urllib3.exceptions.MaxRetryError: HTTPConnectionPool(host='localhost', port=8097): Max retries exceeded with url: /events (Caused by NewConnectionError('<urllib3.connection.HTTPConnection object at 0x7fcd7b5edc10>: Failed to establish a new connection: [Errno 111] Connection refused'))

During handling of the above exception, another exception occurred:

Traceback (most recent call last):
  File "/usr/itetnas04/data-scratch-01/dlim_03hs20/data/conda_envs/machineLearning/lib/python3.7/site-packages/visdom/__init__.py", line 711, in _send
    data=json.dumps(msg),
  File "/usr/itetnas04/data-scratch-01/dlim_03hs20/data/conda_envs/machineLearning/lib/python3.7/site-packages/visdom/__init__.py", line 677, in _handle_post
    r = self.session.post(url, data=data)
  File "/usr/itetnas04/data-scratch-01/dlim_03hs20/data/conda_envs/machineLearning/lib/python3.7/site-packages/requests/sessions.py", line 578, in post
    return self.request('POST', url, data=data, json=json, **kwargs)
  File "/usr/itetnas04/data-scratch-01/dlim_03hs20/data/conda_envs/machineLearning/lib/python3.7/site-packages/requests/sessions.py", line 530, in request
    resp = self.send(prep, **send_kwargs)
  File "/usr/itetnas04/data-scratch-01/dlim_03hs20/data/conda_envs/machineLearning/lib/python3.7/site-packages/requests/sessions.py", line 643, in send
    r = adapter.send(request, **kwargs)
  File "/usr/itetnas04/data-scratch-01/dlim_03hs20/data/conda_envs/machineLearning/lib/python3.7/site-packages/requests/adapters.py", line 516, in send
    raise ConnectionError(e, request=request)
requests.exceptions.ConnectionError: HTTPConnectionPool(host='localhost', port=8097): Max retries exceeded with url: /events (Caused by NewConnectionError('<urllib3.connection.HTTPConnection object at 0x7fcd7b5edc10>: Failed to establish a new connection: [Errno 111] Connection refused'))
Traceback (most recent call last):
  File "/usr/itetnas04/data-scratch-01/dlim_03hs20/data/conda_envs/machineLearning/lib/python3.7/site-packages/urllib3/connection.py", line 160, in _new_conn
    (self._dns_host, self.port), self.timeout, **extra_kw
  File "/usr/itetnas04/data-scratch-01/dlim_03hs20/data/conda_envs/machineLearning/lib/python3.7/site-packages/urllib3/util/connection.py", line 84, in create_connection
    raise err
  File "/usr/itetnas04/data-scratch-01/dlim_03hs20/data/conda_envs/machineLearning/lib/python3.7/site-packages/urllib3/util/connection.py", line 74, in create_connection
    sock.connect(sa)
ConnectionRefusedError: [Errno 111] Connection refused

During handling of the above exception, another exception occurred:

Traceback (most recent call last):
  File "/usr/itetnas04/data-scratch-01/dlim_03hs20/data/conda_envs/machineLearning/lib/python3.7/site-packages/urllib3/connectionpool.py", line 677, in urlopen
    chunked=chunked,
  File "/usr/itetnas04/data-scratch-01/dlim_03hs20/data/conda_envs/machineLearning/lib/python3.7/site-packages/urllib3/connectionpool.py", line 392, in _make_request
    conn.request(method, url, **httplib_request_kw)
  File "/usr/itetnas04/data-scratch-01/dlim_03hs20/data/conda_envs/machineLearning/lib/python3.7/http/client.py", line 1277, in request
    self._send_request(method, url, body, headers, encode_chunked)
  File "/usr/itetnas04/data-scratch-01/dlim_03hs20/data/conda_envs/machineLearning/lib/python3.7/http/client.py", line 1323, in _send_request
    self.endheaders(body, encode_chunked=encode_chunked)
  File "/usr/itetnas04/data-scratch-01/dlim_03hs20/data/conda_envs/machineLearning/lib/python3.7/http/client.py", line 1272, in endheaders
    self._send_output(message_body, encode_chunked=encode_chunked)
  File "/usr/itetnas04/data-scratch-01/dlim_03hs20/data/conda_envs/machineLearning/lib/python3.7/http/client.py", line 1032, in _send_output
    self.send(msg)
  File "/usr/itetnas04/data-scratch-01/dlim_03hs20/data/conda_envs/machineLearning/lib/python3.7/http/client.py", line 972, in send
    self.connect()
  File "/usr/itetnas04/data-scratch-01/dlim_03hs20/data/conda_envs/machineLearning/lib/python3.7/site-packages/urllib3/connection.py", line 187, in connect
    conn = self._new_conn()
  File "/usr/itetnas04/data-scratch-01/dlim_03hs20/data/conda_envs/machineLearning/lib/python3.7/site-packages/urllib3/connection.py", line 172, in _new_conn
    self, "Failed to establish a new connection: %s" % e
urllib3.exceptions.NewConnectionError: <urllib3.connection.HTTPConnection object at 0x7fcd7a407550>: Failed to establish a new connection: [Errno 111] Connection refused

During handling of the above exception, another exception occurred:

Traceback (most recent call last):
  File "/usr/itetnas04/data-scratch-01/dlim_03hs20/data/conda_envs/machineLearning/lib/python3.7/site-packages/requests/adapters.py", line 449, in send
    timeout=timeout
  File "/usr/itetnas04/data-scratch-01/dlim_03hs20/data/conda_envs/machineLearning/lib/python3.7/site-packages/urllib3/connectionpool.py", line 727, in urlopen
    method, url, error=e, _pool=self, _stacktrace=sys.exc_info()[2]
  File "/usr/itetnas04/data-scratch-01/dlim_03hs20/data/conda_envs/machineLearning/lib/python3.7/site-packages/urllib3/util/retry.py", line 439, in increment
    raise MaxRetryError(_pool, url, error or ResponseError(cause))
urllib3.exceptions.MaxRetryError: HTTPConnectionPool(host='localhost', port=8097): Max retries exceeded with url: /events (Caused by NewConnectionError('<urllib3.connection.HTTPConnection object at 0x7fcd7a407550>: Failed to establish a new connection: [Errno 111] Connection refused'))

During handling of the above exception, another exception occurred:

Traceback (most recent call last):
  File "/usr/itetnas04/data-scratch-01/dlim_03hs20/data/conda_envs/machineLearning/lib/python3.7/site-packages/visdom/__init__.py", line 711, in _send
    data=json.dumps(msg),
  File "/usr/itetnas04/data-scratch-01/dlim_03hs20/data/conda_envs/machineLearning/lib/python3.7/site-packages/visdom/__init__.py", line 677, in _handle_post
    r = self.session.post(url, data=data)
  File "/usr/itetnas04/data-scratch-01/dlim_03hs20/data/conda_envs/machineLearning/lib/python3.7/site-packages/requests/sessions.py", line 578, in post
    return self.request('POST', url, data=data, json=json, **kwargs)
  File "/usr/itetnas04/data-scratch-01/dlim_03hs20/data/conda_envs/machineLearning/lib/python3.7/site-packages/requests/sessions.py", line 530, in request
    resp = self.send(prep, **send_kwargs)
  File "/usr/itetnas04/data-scratch-01/dlim_03hs20/data/conda_envs/machineLearning/lib/python3.7/site-packages/requests/sessions.py", line 643, in send
    r = adapter.send(request, **kwargs)
  File "/usr/itetnas04/data-scratch-01/dlim_03hs20/data/conda_envs/machineLearning/lib/python3.7/site-packages/requests/adapters.py", line 516, in send
    raise ConnectionError(e, request=request)
requests.exceptions.ConnectionError: HTTPConnectionPool(host='localhost', port=8097): Max retries exceeded with url: /events (Caused by NewConnectionError('<urllib3.connection.HTTPConnection object at 0x7fcd7a407550>: Failed to establish a new connection: [Errno 111] Connection refused'))
Traceback (most recent call last):
  File "/usr/itetnas04/data-scratch-01/dlim_03hs20/data/conda_envs/machineLearning/lib/python3.7/site-packages/urllib3/connection.py", line 160, in _new_conn
    (self._dns_host, self.port), self.timeout, **extra_kw
  File "/usr/itetnas04/data-scratch-01/dlim_03hs20/data/conda_envs/machineLearning/lib/python3.7/site-packages/urllib3/util/connection.py", line 84, in create_connection
    raise err
  File "/usr/itetnas04/data-scratch-01/dlim_03hs20/data/conda_envs/machineLearning/lib/python3.7/site-packages/urllib3/util/connection.py", line 74, in create_connection
    sock.connect(sa)
ConnectionRefusedError: [Errno 111] Connection refused

During handling of the above exception, another exception occurred:

Traceback (most recent call last):
  File "/usr/itetnas04/data-scratch-01/dlim_03hs20/data/conda_envs/machineLearning/lib/python3.7/site-packages/urllib3/connectionpool.py", line 677, in urlopen
    chunked=chunked,
  File "/usr/itetnas04/data-scratch-01/dlim_03hs20/data/conda_envs/machineLearning/lib/python3.7/site-packages/urllib3/connectionpool.py", line 392, in _make_request
    conn.request(method, url, **httplib_request_kw)
  File "/usr/itetnas04/data-scratch-01/dlim_03hs20/data/conda_envs/machineLearning/lib/python3.7/http/client.py", line 1277, in request
    self._send_request(method, url, body, headers, encode_chunked)
  File "/usr/itetnas04/data-scratch-01/dlim_03hs20/data/conda_envs/machineLearning/lib/python3.7/http/client.py", line 1323, in _send_request
    self.endheaders(body, encode_chunked=encode_chunked)
  File "/usr/itetnas04/data-scratch-01/dlim_03hs20/data/conda_envs/machineLearning/lib/python3.7/http/client.py", line 1272, in endheaders
    self._send_output(message_body, encode_chunked=encode_chunked)
  File "/usr/itetnas04/data-scratch-01/dlim_03hs20/data/conda_envs/machineLearning/lib/python3.7/http/client.py", line 1032, in _send_output
    self.send(msg)
  File "/usr/itetnas04/data-scratch-01/dlim_03hs20/data/conda_envs/machineLearning/lib/python3.7/http/client.py", line 972, in send
    self.connect()
  File "/usr/itetnas04/data-scratch-01/dlim_03hs20/data/conda_envs/machineLearning/lib/python3.7/site-packages/urllib3/connection.py", line 187, in connect
    conn = self._new_conn()
  File "/usr/itetnas04/data-scratch-01/dlim_03hs20/data/conda_envs/machineLearning/lib/python3.7/site-packages/urllib3/connection.py", line 172, in _new_conn
    self, "Failed to establish a new connection: %s" % e
urllib3.exceptions.NewConnectionError: <urllib3.connection.HTTPConnection object at 0x7fcd7a407e10>: Failed to establish a new connection: [Errno 111] Connection refused

During handling of the above exception, another exception occurred:

Traceback (most recent call last):
  File "/usr/itetnas04/data-scratch-01/dlim_03hs20/data/conda_envs/machineLearning/lib/python3.7/site-packages/requests/adapters.py", line 449, in send
    timeout=timeout
  File "/usr/itetnas04/data-scratch-01/dlim_03hs20/data/conda_envs/machineLearning/lib/python3.7/site-packages/urllib3/connectionpool.py", line 727, in urlopen
    method, url, error=e, _pool=self, _stacktrace=sys.exc_info()[2]
  File "/usr/itetnas04/data-scratch-01/dlim_03hs20/data/conda_envs/machineLearning/lib/python3.7/site-packages/urllib3/util/retry.py", line 439, in increment
    raise MaxRetryError(_pool, url, error or ResponseError(cause))
urllib3.exceptions.MaxRetryError: HTTPConnectionPool(host='localhost', port=8097): Max retries exceeded with url: /events (Caused by NewConnectionError('<urllib3.connection.HTTPConnection object at 0x7fcd7a407e10>: Failed to establish a new connection: [Errno 111] Connection refused'))

During handling of the above exception, another exception occurred:

Traceback (most recent call last):
  File "/usr/itetnas04/data-scratch-01/dlim_03hs20/data/conda_envs/machineLearning/lib/python3.7/site-packages/visdom/__init__.py", line 711, in _send
    data=json.dumps(msg),
  File "/usr/itetnas04/data-scratch-01/dlim_03hs20/data/conda_envs/machineLearning/lib/python3.7/site-packages/visdom/__init__.py", line 677, in _handle_post
    r = self.session.post(url, data=data)
  File "/usr/itetnas04/data-scratch-01/dlim_03hs20/data/conda_envs/machineLearning/lib/python3.7/site-packages/requests/sessions.py", line 578, in post
    return self.request('POST', url, data=data, json=json, **kwargs)
  File "/usr/itetnas04/data-scratch-01/dlim_03hs20/data/conda_envs/machineLearning/lib/python3.7/site-packages/requests/sessions.py", line 530, in request
    resp = self.send(prep, **send_kwargs)
  File "/usr/itetnas04/data-scratch-01/dlim_03hs20/data/conda_envs/machineLearning/lib/python3.7/site-packages/requests/sessions.py", line 643, in send
    r = adapter.send(request, **kwargs)
  File "/usr/itetnas04/data-scratch-01/dlim_03hs20/data/conda_envs/machineLearning/lib/python3.7/site-packages/requests/adapters.py", line 516, in send
    raise ConnectionError(e, request=request)
requests.exceptions.ConnectionError: HTTPConnectionPool(host='localhost', port=8097): Max retries exceeded with url: /events (Caused by NewConnectionError('<urllib3.connection.HTTPConnection object at 0x7fcd7a407e10>: Failed to establish a new connection: [Errno 111] Connection refused'))
Traceback (most recent call last):
  File "/usr/itetnas04/data-scratch-01/dlim_03hs20/data/conda_envs/machineLearning/lib/python3.7/site-packages/urllib3/connection.py", line 160, in _new_conn
    (self._dns_host, self.port), self.timeout, **extra_kw
  File "/usr/itetnas04/data-scratch-01/dlim_03hs20/data/conda_envs/machineLearning/lib/python3.7/site-packages/urllib3/util/connection.py", line 84, in create_connection
    raise err
  File "/usr/itetnas04/data-scratch-01/dlim_03hs20/data/conda_envs/machineLearning/lib/python3.7/site-packages/urllib3/util/connection.py", line 74, in create_connection
    sock.connect(sa)
ConnectionRefusedError: [Errno 111] Connection refused

During handling of the above exception, another exception occurred:

Traceback (most recent call last):
  File "/usr/itetnas04/data-scratch-01/dlim_03hs20/data/conda_envs/machineLearning/lib/python3.7/site-packages/urllib3/connectionpool.py", line 677, in urlopen
    chunked=chunked,
  File "/usr/itetnas04/data-scratch-01/dlim_03hs20/data/conda_envs/machineLearning/lib/python3.7/site-packages/urllib3/connectionpool.py", line 392, in _make_request
    conn.request(method, url, **httplib_request_kw)
  File "/usr/itetnas04/data-scratch-01/dlim_03hs20/data/conda_envs/machineLearning/lib/python3.7/http/client.py", line 1277, in request
    self._send_request(method, url, body, headers, encode_chunked)
  File "/usr/itetnas04/data-scratch-01/dlim_03hs20/data/conda_envs/machineLearning/lib/python3.7/http/client.py", line 1323, in _send_request
    self.endheaders(body, encode_chunked=encode_chunked)
  File "/usr/itetnas04/data-scratch-01/dlim_03hs20/data/conda_envs/machineLearning/lib/python3.7/http/client.py", line 1272, in endheaders
    self._send_output(message_body, encode_chunked=encode_chunked)
  File "/usr/itetnas04/data-scratch-01/dlim_03hs20/data/conda_envs/machineLearning/lib/python3.7/http/client.py", line 1032, in _send_output
    self.send(msg)
  File "/usr/itetnas04/data-scratch-01/dlim_03hs20/data/conda_envs/machineLearning/lib/python3.7/http/client.py", line 972, in send
    self.connect()
  File "/usr/itetnas04/data-scratch-01/dlim_03hs20/data/conda_envs/machineLearning/lib/python3.7/site-packages/urllib3/connection.py", line 187, in connect
    conn = self._new_conn()
  File "/usr/itetnas04/data-scratch-01/dlim_03hs20/data/conda_envs/machineLearning/lib/python3.7/site-packages/urllib3/connection.py", line 172, in _new_conn
    self, "Failed to establish a new connection: %s" % e
urllib3.exceptions.NewConnectionError: <urllib3.connection.HTTPConnection object at 0x7fcd7a403fd0>: Failed to establish a new connection: [Errno 111] Connection refused

During handling of the above exception, another exception occurred:

Traceback (most recent call last):
  File "/usr/itetnas04/data-scratch-01/dlim_03hs20/data/conda_envs/machineLearning/lib/python3.7/site-packages/requests/adapters.py", line 449, in send
    timeout=timeout
  File "/usr/itetnas04/data-scratch-01/dlim_03hs20/data/conda_envs/machineLearning/lib/python3.7/site-packages/urllib3/connectionpool.py", line 727, in urlopen
    method, url, error=e, _pool=self, _stacktrace=sys.exc_info()[2]
  File "/usr/itetnas04/data-scratch-01/dlim_03hs20/data/conda_envs/machineLearning/lib/python3.7/site-packages/urllib3/util/retry.py", line 439, in increment
    raise MaxRetryError(_pool, url, error or ResponseError(cause))
urllib3.exceptions.MaxRetryError: HTTPConnectionPool(host='localhost', port=8097): Max retries exceeded with url: /events (Caused by NewConnectionError('<urllib3.connection.HTTPConnection object at 0x7fcd7a403fd0>: Failed to establish a new connection: [Errno 111] Connection refused'))

During handling of the above exception, another exception occurred:

Traceback (most recent call last):
  File "/usr/itetnas04/data-scratch-01/dlim_03hs20/data/conda_envs/machineLearning/lib/python3.7/site-packages/visdom/__init__.py", line 711, in _send
    data=json.dumps(msg),
  File "/usr/itetnas04/data-scratch-01/dlim_03hs20/data/conda_envs/machineLearning/lib/python3.7/site-packages/visdom/__init__.py", line 677, in _handle_post
    r = self.session.post(url, data=data)
  File "/usr/itetnas04/data-scratch-01/dlim_03hs20/data/conda_envs/machineLearning/lib/python3.7/site-packages/requests/sessions.py", line 578, in post
    return self.request('POST', url, data=data, json=json, **kwargs)
  File "/usr/itetnas04/data-scratch-01/dlim_03hs20/data/conda_envs/machineLearning/lib/python3.7/site-packages/requests/sessions.py", line 530, in request
    resp = self.send(prep, **send_kwargs)
  File "/usr/itetnas04/data-scratch-01/dlim_03hs20/data/conda_envs/machineLearning/lib/python3.7/site-packages/requests/sessions.py", line 643, in send
    r = adapter.send(request, **kwargs)
  File "/usr/itetnas04/data-scratch-01/dlim_03hs20/data/conda_envs/machineLearning/lib/python3.7/site-packages/requests/adapters.py", line 516, in send
    raise ConnectionError(e, request=request)
requests.exceptions.ConnectionError: HTTPConnectionPool(host='localhost', port=8097): Max retries exceeded with url: /events (Caused by NewConnectionError('<urllib3.connection.HTTPConnection object at 0x7fcd7a403fd0>: Failed to establish a new connection: [Errno 111] Connection refused'))
Traceback (most recent call last):
  File "/usr/itetnas04/data-scratch-01/dlim_03hs20/data/conda_envs/machineLearning/lib/python3.7/site-packages/urllib3/connection.py", line 160, in _new_conn
    (self._dns_host, self.port), self.timeout, **extra_kw
  File "/usr/itetnas04/data-scratch-01/dlim_03hs20/data/conda_envs/machineLearning/lib/python3.7/site-packages/urllib3/util/connection.py", line 84, in create_connection
    raise err
  File "/usr/itetnas04/data-scratch-01/dlim_03hs20/data/conda_envs/machineLearning/lib/python3.7/site-packages/urllib3/util/connection.py", line 74, in create_connection
    sock.connect(sa)
ConnectionRefusedError: [Errno 111] Connection refused

During handling of the above exception, another exception occurred:

Traceback (most recent call last):
  File "/usr/itetnas04/data-scratch-01/dlim_03hs20/data/conda_envs/machineLearning/lib/python3.7/site-packages/urllib3/connectionpool.py", line 677, in urlopen
    chunked=chunked,
  File "/usr/itetnas04/data-scratch-01/dlim_03hs20/data/conda_envs/machineLearning/lib/python3.7/site-packages/urllib3/connectionpool.py", line 392, in _make_request
    conn.request(method, url, **httplib_request_kw)
  File "/usr/itetnas04/data-scratch-01/dlim_03hs20/data/conda_envs/machineLearning/lib/python3.7/http/client.py", line 1277, in request
    self._send_request(method, url, body, headers, encode_chunked)
  File "/usr/itetnas04/data-scratch-01/dlim_03hs20/data/conda_envs/machineLearning/lib/python3.7/http/client.py", line 1323, in _send_request
    self.endheaders(body, encode_chunked=encode_chunked)
  File "/usr/itetnas04/data-scratch-01/dlim_03hs20/data/conda_envs/machineLearning/lib/python3.7/http/client.py", line 1272, in endheaders
    self._send_output(message_body, encode_chunked=encode_chunked)
  File "/usr/itetnas04/data-scratch-01/dlim_03hs20/data/conda_envs/machineLearning/lib/python3.7/http/client.py", line 1032, in _send_output
    self.send(msg)
  File "/usr/itetnas04/data-scratch-01/dlim_03hs20/data/conda_envs/machineLearning/lib/python3.7/http/client.py", line 972, in send
    self.connect()
  File "/usr/itetnas04/data-scratch-01/dlim_03hs20/data/conda_envs/machineLearning/lib/python3.7/site-packages/urllib3/connection.py", line 187, in connect
    conn = self._new_conn()
  File "/usr/itetnas04/data-scratch-01/dlim_03hs20/data/conda_envs/machineLearning/lib/python3.7/site-packages/urllib3/connection.py", line 172, in _new_conn
    self, "Failed to establish a new connection: %s" % e
urllib3.exceptions.NewConnectionError: <urllib3.connection.HTTPConnection object at 0x7fcd7b5ed210>: Failed to establish a new connection: [Errno 111] Connection refused

During handling of the above exception, another exception occurred:

Traceback (most recent call last):
  File "/usr/itetnas04/data-scratch-01/dlim_03hs20/data/conda_envs/machineLearning/lib/python3.7/site-packages/requests/adapters.py", line 449, in send
    timeout=timeout
  File "/usr/itetnas04/data-scratch-01/dlim_03hs20/data/conda_envs/machineLearning/lib/python3.7/site-packages/urllib3/connectionpool.py", line 727, in urlopen
    method, url, error=e, _pool=self, _stacktrace=sys.exc_info()[2]
  File "/usr/itetnas04/data-scratch-01/dlim_03hs20/data/conda_envs/machineLearning/lib/python3.7/site-packages/urllib3/util/retry.py", line 439, in increment
    raise MaxRetryError(_pool, url, error or ResponseError(cause))
urllib3.exceptions.MaxRetryError: HTTPConnectionPool(host='localhost', port=8097): Max retries exceeded with url: /events (Caused by NewConnectionError('<urllib3.connection.HTTPConnection object at 0x7fcd7b5ed210>: Failed to establish a new connection: [Errno 111] Connection refused'))

During handling of the above exception, another exception occurred:

Traceback (most recent call last):
  File "/usr/itetnas04/data-scratch-01/dlim_03hs20/data/conda_envs/machineLearning/lib/python3.7/site-packages/visdom/__init__.py", line 711, in _send
    data=json.dumps(msg),
  File "/usr/itetnas04/data-scratch-01/dlim_03hs20/data/conda_envs/machineLearning/lib/python3.7/site-packages/visdom/__init__.py", line 677, in _handle_post
    r = self.session.post(url, data=data)
  File "/usr/itetnas04/data-scratch-01/dlim_03hs20/data/conda_envs/machineLearning/lib/python3.7/site-packages/requests/sessions.py", line 578, in post
    return self.request('POST', url, data=data, json=json, **kwargs)
  File "/usr/itetnas04/data-scratch-01/dlim_03hs20/data/conda_envs/machineLearning/lib/python3.7/site-packages/requests/sessions.py", line 530, in request
    resp = self.send(prep, **send_kwargs)
  File "/usr/itetnas04/data-scratch-01/dlim_03hs20/data/conda_envs/machineLearning/lib/python3.7/site-packages/requests/sessions.py", line 643, in send
    r = adapter.send(request, **kwargs)
  File "/usr/itetnas04/data-scratch-01/dlim_03hs20/data/conda_envs/machineLearning/lib/python3.7/site-packages/requests/adapters.py", line 516, in send
    raise ConnectionError(e, request=request)
requests.exceptions.ConnectionError: HTTPConnectionPool(host='localhost', port=8097): Max retries exceeded with url: /events (Caused by NewConnectionError('<urllib3.connection.HTTPConnection object at 0x7fcd7b5ed210>: Failed to establish a new connection: [Errno 111] Connection refused'))
Traceback (most recent call last):
  File "/usr/itetnas04/data-scratch-01/dlim_03hs20/data/conda_envs/machineLearning/lib/python3.7/site-packages/urllib3/connection.py", line 160, in _new_conn
    (self._dns_host, self.port), self.timeout, **extra_kw
  File "/usr/itetnas04/data-scratch-01/dlim_03hs20/data/conda_envs/machineLearning/lib/python3.7/site-packages/urllib3/util/connection.py", line 84, in create_connection
    raise err
  File "/usr/itetnas04/data-scratch-01/dlim_03hs20/data/conda_envs/machineLearning/lib/python3.7/site-packages/urllib3/util/connection.py", line 74, in create_connection
    sock.connect(sa)
ConnectionRefusedError: [Errno 111] Connection refused

During handling of the above exception, another exception occurred:

Traceback (most recent call last):
  File "/usr/itetnas04/data-scratch-01/dlim_03hs20/data/conda_envs/machineLearning/lib/python3.7/site-packages/urllib3/connectionpool.py", line 677, in urlopen
    chunked=chunked,
  File "/usr/itetnas04/data-scratch-01/dlim_03hs20/data/conda_envs/machineLearning/lib/python3.7/site-packages/urllib3/connectionpool.py", line 392, in _make_request
    conn.request(method, url, **httplib_request_kw)
  File "/usr/itetnas04/data-scratch-01/dlim_03hs20/data/conda_envs/machineLearning/lib/python3.7/http/client.py", line 1277, in request
    self._send_request(method, url, body, headers, encode_chunked)
  File "/usr/itetnas04/data-scratch-01/dlim_03hs20/data/conda_envs/machineLearning/lib/python3.7/http/client.py", line 1323, in _send_request
    self.endheaders(body, encode_chunked=encode_chunked)
  File "/usr/itetnas04/data-scratch-01/dlim_03hs20/data/conda_envs/machineLearning/lib/python3.7/http/client.py", line 1272, in endheaders
    self._send_output(message_body, encode_chunked=encode_chunked)
  File "/usr/itetnas04/data-scratch-01/dlim_03hs20/data/conda_envs/machineLearning/lib/python3.7/http/client.py", line 1032, in _send_output
    self.send(msg)
  File "/usr/itetnas04/data-scratch-01/dlim_03hs20/data/conda_envs/machineLearning/lib/python3.7/http/client.py", line 972, in send
    self.connect()
  File "/usr/itetnas04/data-scratch-01/dlim_03hs20/data/conda_envs/machineLearning/lib/python3.7/site-packages/urllib3/connection.py", line 187, in connect
    conn = self._new_conn()
  File "/usr/itetnas04/data-scratch-01/dlim_03hs20/data/conda_envs/machineLearning/lib/python3.7/site-packages/urllib3/connection.py", line 172, in _new_conn
    self, "Failed to establish a new connection: %s" % e
urllib3.exceptions.NewConnectionError: <urllib3.connection.HTTPConnection object at 0x7fcd7a410150>: Failed to establish a new connection: [Errno 111] Connection refused

During handling of the above exception, another exception occurred:

Traceback (most recent call last):
  File "/usr/itetnas04/data-scratch-01/dlim_03hs20/data/conda_envs/machineLearning/lib/python3.7/site-packages/requests/adapters.py", line 449, in send
    timeout=timeout
  File "/usr/itetnas04/data-scratch-01/dlim_03hs20/data/conda_envs/machineLearning/lib/python3.7/site-packages/urllib3/connectionpool.py", line 727, in urlopen
    method, url, error=e, _pool=self, _stacktrace=sys.exc_info()[2]
  File "/usr/itetnas04/data-scratch-01/dlim_03hs20/data/conda_envs/machineLearning/lib/python3.7/site-packages/urllib3/util/retry.py", line 439, in increment
    raise MaxRetryError(_pool, url, error or ResponseError(cause))
urllib3.exceptions.MaxRetryError: HTTPConnectionPool(host='localhost', port=8097): Max retries exceeded with url: /events (Caused by NewConnectionError('<urllib3.connection.HTTPConnection object at 0x7fcd7a410150>: Failed to establish a new connection: [Errno 111] Connection refused'))

During handling of the above exception, another exception occurred:

Traceback (most recent call last):
  File "/usr/itetnas04/data-scratch-01/dlim_03hs20/data/conda_envs/machineLearning/lib/python3.7/site-packages/visdom/__init__.py", line 711, in _send
    data=json.dumps(msg),
  File "/usr/itetnas04/data-scratch-01/dlim_03hs20/data/conda_envs/machineLearning/lib/python3.7/site-packages/visdom/__init__.py", line 677, in _handle_post
    r = self.session.post(url, data=data)
  File "/usr/itetnas04/data-scratch-01/dlim_03hs20/data/conda_envs/machineLearning/lib/python3.7/site-packages/requests/sessions.py", line 578, in post
    return self.request('POST', url, data=data, json=json, **kwargs)
  File "/usr/itetnas04/data-scratch-01/dlim_03hs20/data/conda_envs/machineLearning/lib/python3.7/site-packages/requests/sessions.py", line 530, in request
    resp = self.send(prep, **send_kwargs)
  File "/usr/itetnas04/data-scratch-01/dlim_03hs20/data/conda_envs/machineLearning/lib/python3.7/site-packages/requests/sessions.py", line 643, in send
    r = adapter.send(request, **kwargs)
  File "/usr/itetnas04/data-scratch-01/dlim_03hs20/data/conda_envs/machineLearning/lib/python3.7/site-packages/requests/adapters.py", line 516, in send
    raise ConnectionError(e, request=request)
requests.exceptions.ConnectionError: HTTPConnectionPool(host='localhost', port=8097): Max retries exceeded with url: /events (Caused by NewConnectionError('<urllib3.connection.HTTPConnection object at 0x7fcd7a410150>: Failed to establish a new connection: [Errno 111] Connection refused'))
Traceback (most recent call last):
  File "/usr/itetnas04/data-scratch-01/dlim_03hs20/data/conda_envs/machineLearning/lib/python3.7/site-packages/urllib3/connection.py", line 160, in _new_conn
    (self._dns_host, self.port), self.timeout, **extra_kw
  File "/usr/itetnas04/data-scratch-01/dlim_03hs20/data/conda_envs/machineLearning/lib/python3.7/site-packages/urllib3/util/connection.py", line 84, in create_connection
    raise err
  File "/usr/itetnas04/data-scratch-01/dlim_03hs20/data/conda_envs/machineLearning/lib/python3.7/site-packages/urllib3/util/connection.py", line 74, in create_connection
    sock.connect(sa)
ConnectionRefusedError: [Errno 111] Connection refused

During handling of the above exception, another exception occurred:

Traceback (most recent call last):
  File "/usr/itetnas04/data-scratch-01/dlim_03hs20/data/conda_envs/machineLearning/lib/python3.7/site-packages/urllib3/connectionpool.py", line 677, in urlopen
    chunked=chunked,
  File "/usr/itetnas04/data-scratch-01/dlim_03hs20/data/conda_envs/machineLearning/lib/python3.7/site-packages/urllib3/connectionpool.py", line 392, in _make_request
    conn.request(method, url, **httplib_request_kw)
  File "/usr/itetnas04/data-scratch-01/dlim_03hs20/data/conda_envs/machineLearning/lib/python3.7/http/client.py", line 1277, in request
    self._send_request(method, url, body, headers, encode_chunked)
  File "/usr/itetnas04/data-scratch-01/dlim_03hs20/data/conda_envs/machineLearning/lib/python3.7/http/client.py", line 1323, in _send_request
    self.endheaders(body, encode_chunked=encode_chunked)
  File "/usr/itetnas04/data-scratch-01/dlim_03hs20/data/conda_envs/machineLearning/lib/python3.7/http/client.py", line 1272, in endheaders
    self._send_output(message_body, encode_chunked=encode_chunked)
  File "/usr/itetnas04/data-scratch-01/dlim_03hs20/data/conda_envs/machineLearning/lib/python3.7/http/client.py", line 1032, in _send_output
    self.send(msg)
  File "/usr/itetnas04/data-scratch-01/dlim_03hs20/data/conda_envs/machineLearning/lib/python3.7/http/client.py", line 972, in send
    self.connect()
  File "/usr/itetnas04/data-scratch-01/dlim_03hs20/data/conda_envs/machineLearning/lib/python3.7/site-packages/urllib3/connection.py", line 187, in connect
    conn = self._new_conn()
  File "/usr/itetnas04/data-scratch-01/dlim_03hs20/data/conda_envs/machineLearning/lib/python3.7/site-packages/urllib3/connection.py", line 172, in _new_conn
    self, "Failed to establish a new connection: %s" % e
urllib3.exceptions.NewConnectionError: <urllib3.connection.HTTPConnection object at 0x7fcd7b5ede10>: Failed to establish a new connection: [Errno 111] Connection refused

During handling of the above exception, another exception occurred:

Traceback (most recent call last):
  File "/usr/itetnas04/data-scratch-01/dlim_03hs20/data/conda_envs/machineLearning/lib/python3.7/site-packages/requests/adapters.py", line 449, in send
    timeout=timeout
  File "/usr/itetnas04/data-scratch-01/dlim_03hs20/data/conda_envs/machineLearning/lib/python3.7/site-packages/urllib3/connectionpool.py", line 727, in urlopen
    method, url, error=e, _pool=self, _stacktrace=sys.exc_info()[2]
  File "/usr/itetnas04/data-scratch-01/dlim_03hs20/data/conda_envs/machineLearning/lib/python3.7/site-packages/urllib3/util/retry.py", line 439, in increment
    raise MaxRetryError(_pool, url, error or ResponseError(cause))
urllib3.exceptions.MaxRetryError: HTTPConnectionPool(host='localhost', port=8097): Max retries exceeded with url: /events (Caused by NewConnectionError('<urllib3.connection.HTTPConnection object at 0x7fcd7b5ede10>: Failed to establish a new connection: [Errno 111] Connection refused'))

During handling of the above exception, another exception occurred:

Traceback (most recent call last):
  File "/usr/itetnas04/data-scratch-01/dlim_03hs20/data/conda_envs/machineLearning/lib/python3.7/site-packages/visdom/__init__.py", line 711, in _send
    data=json.dumps(msg),
  File "/usr/itetnas04/data-scratch-01/dlim_03hs20/data/conda_envs/machineLearning/lib/python3.7/site-packages/visdom/__init__.py", line 677, in _handle_post
    r = self.session.post(url, data=data)
  File "/usr/itetnas04/data-scratch-01/dlim_03hs20/data/conda_envs/machineLearning/lib/python3.7/site-packages/requests/sessions.py", line 578, in post
    return self.request('POST', url, data=data, json=json, **kwargs)
  File "/usr/itetnas04/data-scratch-01/dlim_03hs20/data/conda_envs/machineLearning/lib/python3.7/site-packages/requests/sessions.py", line 530, in request
    resp = self.send(prep, **send_kwargs)
  File "/usr/itetnas04/data-scratch-01/dlim_03hs20/data/conda_envs/machineLearning/lib/python3.7/site-packages/requests/sessions.py", line 643, in send
    r = adapter.send(request, **kwargs)
  File "/usr/itetnas04/data-scratch-01/dlim_03hs20/data/conda_envs/machineLearning/lib/python3.7/site-packages/requests/adapters.py", line 516, in send
    raise ConnectionError(e, request=request)
requests.exceptions.ConnectionError: HTTPConnectionPool(host='localhost', port=8097): Max retries exceeded with url: /events (Caused by NewConnectionError('<urllib3.connection.HTTPConnection object at 0x7fcd7b5ede10>: Failed to establish a new connection: [Errno 111] Connection refused'))
(epoch: 5, iters: 100, time: 0.060, data: 0.203) G_GAN: 3.271 G_L1: 38.285 D_real: 0.034 D_fake: 0.107 
Exception in user code:
------------------------------------------------------------
(epoch: 5, iters: 200, time: 0.058, data: 0.002) G_GAN: 2.208 G_L1: 38.070 D_real: 0.010 D_fake: 0.650 
Exception in user code:
------------------------------------------------------------
(epoch: 5, iters: 300, time: 0.057, data: 0.002) G_GAN: 4.467 G_L1: 43.647 D_real: 0.049 D_fake: 0.020 
Exception in user code:
------------------------------------------------------------
Exception in user code:
------------------------------------------------------------
Exception in user code:
------------------------------------------------------------
(epoch: 5, iters: 400, time: 0.256, data: 0.002) G_GAN: 1.999 G_L1: 27.549 D_real: 0.025 D_fake: 0.500 
Exception in user code:
------------------------------------------------------------
saving the model at the end of epoch 5, iters 2000
Traceback (most recent call last):
  File "./train.py", line 74, in <module>
    model.save_networks('latest')
  File "/usr/itetnas04/data-scratch-01/dlim_03hs20/data/DLIM/models/base_model.py", line 157, in save_networks
    if sesam and name == 'D':
NameError: name 'sesam' is not defined
----------------- Options ---------------
             aspect_ratio: 1.0                           
               batch_size: 1                             
          checkpoints_dir: ./checkpoints                 
                crop_size: 256                           
                 dataroot: ./datasets/facades            	[default: None]
             dataset_mode: aligned                       
                direction: BtoA                          	[default: AtoB]
          display_winsize: 256                           
                    epoch: latest                        
                     eval: False                         
                  gpu_ids: 0                             
                init_gain: 0.02                          
                init_type: normal                        
                 input_nc: 3                             
                  isTrain: False                         	[default: None]
                load_iter: 0                             	[default: 0]
                load_size: 256                           
         max_dataset_size: inf                           
                    model: stochastic                    	[default: test]
               n_layers_D: 3                             
                     name: stoch                         	[default: experiment_name]
                      ndf: 64                            
                     netD: basic                         
                     netG: unet_256                      
                      ngf: 64                            
               no_dropout: False                         
                  no_flip: False                         
                     norm: batch                         
                 num_test: 50                            
              num_threads: 4                             
                output_nc: 3                             
                    phase: test                          
               preprocess: resize_and_crop               
              results_dir: ./results/                    
           serial_batches: False                         
                   suffix:                               
                  verbose: False                         
----------------- End -------------------
dataset [AlignedDataset] was created
initialize network with normal
model [StochasticModel] was created
loading the model from ./checkpoints/stoch/latest_net_G.pth
Traceback (most recent call last):
  File "./test.py", line 47, in <module>
    model.setup(opt)               # regular setup: load and print networks; create schedulers
  File "/usr/itetnas04/data-scratch-01/dlim_03hs20/data/DLIM/models/base_model.py", line 88, in setup
    self.load_networks(load_suffix)
  File "/usr/itetnas04/data-scratch-01/dlim_03hs20/data/DLIM/models/base_model.py", line 195, in load_networks
    state_dict = torch.load(load_path, map_location=str(self.device))
  File "/usr/itetnas04/data-scratch-01/dlim_03hs20/data/conda_envs/machineLearning/lib/python3.7/site-packages/torch/serialization.py", line 382, in load
    f = open(f, 'rb')
FileNotFoundError: [Errno 2] No such file or directory: './checkpoints/stoch/latest_net_G.pth'
Creating feature extractor "inception-v3-compat" with features ['logits_unbiased', '2048']
Traceback (most recent call last):
  File "./nicolasScripts/fidelityStochastic.py", line 10, in <module>
    stoch_metrics = calculate_metrics("./results/stoch/test_latest/images/", "./datasets/facades/test/", cuda=False, isc=True, fid=True, kid=False, verbose=True)
  File "/usr/itetnas04/data-scratch-01/dlim_03hs20/data/conda_envs/fidelitySupport/lib/python3.8/site-packages/torch_fidelity/metrics.py", line 118, in calculate_metrics
    cacheable_input1_name = get_input_cacheable_name(input_1, get_kwarg('cache_input1_name', kwargs))
  File "/usr/itetnas04/data-scratch-01/dlim_03hs20/data/conda_envs/fidelitySupport/lib/python3.8/site-packages/torch_fidelity/utils.py", line 118, in get_input_cacheable_name
    raise ValueError(f'Unknown format of input string "{input}"')
ValueError: Unknown format of input string "./results/stoch/test_latest/images/"
